# Generated by BlockArchitect.de
# Structure: A 49 x 49 base for a

setblock ~0 ~0 ~12 minecraft:blackstone
setblock ~0 ~1 ~12 minecraft:blackstone
setblock ~0 ~2 ~12 minecraft:blackstone
setblock ~0 ~3 ~12 minecraft:blackstone
setblock ~0 ~0 ~13 minecraft:blackstone
setblock ~0 ~1 ~13 minecraft:blackstone
setblock ~0 ~2 ~13 minecraft:blackstone
setblock ~0 ~3 ~13 minecraft:blackstone
setblock ~0 ~0 ~14 minecraft:blackstone
setblock ~0 ~1 ~14 minecraft:blackstone
setblock ~0 ~2 ~14 minecraft:blackstone
setblock ~0 ~3 ~14 minecraft:blackstone
setblock ~0 ~0 ~15 minecraft:blackstone
setblock ~0 ~1 ~15 minecraft:blackstone
setblock ~0 ~2 ~15 minecraft:blackstone
setblock ~0 ~3 ~15 minecraft:blackstone
setblock ~0 ~0 ~16 minecraft:blackstone
setblock ~0 ~1 ~16 minecraft:blackstone
setblock ~0 ~2 ~16 minecraft:blackstone
setblock ~0 ~3 ~16 minecraft:blackstone
setblock ~0 ~0 ~17 minecraft:blackstone
setblock ~0 ~1 ~17 minecraft:blackstone
setblock ~0 ~2 ~17 minecraft:blackstone
setblock ~0 ~3 ~17 minecraft:blackstone
setblock ~0 ~0 ~18 minecraft:blackstone
setblock ~0 ~1 ~18 minecraft:blackstone
setblock ~0 ~2 ~18 minecraft:blackstone
setblock ~0 ~3 ~18 minecraft:blackstone
setblock ~1 ~0 ~9 minecraft:blackstone
setblock ~1 ~1 ~9 minecraft:blackstone
setblock ~1 ~2 ~9 minecraft:blackstone
setblock ~1 ~3 ~9 minecraft:blackstone
setblock ~1 ~0 ~10 minecraft:blackstone
setblock ~1 ~1 ~10 minecraft:blackstone
setblock ~1 ~2 ~10 minecraft:blackstone
setblock ~1 ~3 ~10 minecraft:blackstone
setblock ~1 ~0 ~11 minecraft:blackstone
setblock ~1 ~1 ~11 minecraft:blackstone
setblock ~1 ~2 ~11 minecraft:blackstone
setblock ~1 ~3 ~11 minecraft:blackstone
setblock ~1 ~0 ~12 minecraft:blackstone
setblock ~1 ~1 ~12 minecraft:blackstone
setblock ~1 ~2 ~12 minecraft:blackstone
setblock ~1 ~3 ~12 minecraft:blackstone
setblock ~1 ~0 ~13 minecraft:blackstone
setblock ~1 ~1 ~13 minecraft:blackstone
setblock ~1 ~2 ~13 minecraft:blackstone
setblock ~1 ~3 ~13 minecraft:blackstone
setblock ~1 ~0 ~14 minecraft:blackstone
setblock ~1 ~1 ~14 minecraft:blackstone
setblock ~1 ~2 ~14 minecraft:blackstone
setblock ~1 ~3 ~14 minecraft:blackstone
setblock ~1 ~0 ~15 minecraft:blackstone
setblock ~1 ~1 ~15 minecraft:blackstone
setblock ~1 ~2 ~15 minecraft:blackstone
setblock ~1 ~3 ~15 minecraft:blackstone
setblock ~1 ~0 ~16 minecraft:blackstone
setblock ~1 ~1 ~16 minecraft:blackstone
setblock ~1 ~2 ~16 minecraft:blackstone
setblock ~1 ~3 ~16 minecraft:blackstone
setblock ~1 ~0 ~17 minecraft:blackstone
setblock ~1 ~1 ~17 minecraft:blackstone
setblock ~1 ~2 ~17 minecraft:blackstone
setblock ~1 ~3 ~17 minecraft:blackstone
setblock ~1 ~0 ~18 minecraft:blackstone
setblock ~1 ~1 ~18 minecraft:blackstone
setblock ~1 ~2 ~18 minecraft:blackstone
setblock ~1 ~3 ~18 minecraft:blackstone
setblock ~1 ~0 ~19 minecraft:blackstone
setblock ~1 ~1 ~19 minecraft:blackstone
setblock ~1 ~2 ~19 minecraft:blackstone
setblock ~1 ~3 ~19 minecraft:blackstone
setblock ~1 ~0 ~20 minecraft:blackstone
setblock ~1 ~1 ~20 minecraft:blackstone
setblock ~1 ~2 ~20 minecraft:blackstone
setblock ~1 ~3 ~20 minecraft:blackstone
setblock ~1 ~0 ~21 minecraft:blackstone
setblock ~1 ~1 ~21 minecraft:blackstone
setblock ~1 ~2 ~21 minecraft:blackstone
setblock ~1 ~3 ~21 minecraft:blackstone
setblock ~2 ~0 ~7 minecraft:blackstone
setblock ~2 ~1 ~7 minecraft:blackstone
setblock ~2 ~2 ~7 minecraft:blackstone
setblock ~2 ~3 ~7 minecraft:blackstone
setblock ~2 ~0 ~8 minecraft:blackstone
setblock ~2 ~1 ~8 minecraft:blackstone
setblock ~2 ~2 ~8 minecraft:blackstone
setblock ~2 ~3 ~8 minecraft:blackstone
setblock ~2 ~0 ~9 minecraft:blackstone
setblock ~2 ~1 ~9 minecraft:blackstone
setblock ~2 ~2 ~9 minecraft:blackstone
setblock ~2 ~3 ~9 minecraft:blackstone
setblock ~2 ~0 ~10 minecraft:blackstone
setblock ~2 ~1 ~10 minecraft:blackstone
setblock ~2 ~2 ~10 minecraft:blackstone
setblock ~2 ~3 ~10 minecraft:blackstone
setblock ~2 ~0 ~11 minecraft:blackstone
setblock ~2 ~1 ~11 minecraft:blackstone
setblock ~2 ~2 ~11 minecraft:blackstone
setblock ~2 ~3 ~11 minecraft:blackstone
setblock ~2 ~0 ~12 minecraft:blackstone
setblock ~2 ~0 ~13 minecraft:blackstone
setblock ~2 ~0 ~14 minecraft:blackstone
setblock ~2 ~0 ~15 minecraft:blackstone
setblock ~2 ~0 ~16 minecraft:blackstone
setblock ~2 ~0 ~17 minecraft:blackstone
setblock ~2 ~0 ~18 minecraft:blackstone
setblock ~2 ~0 ~19 minecraft:blackstone
setblock ~2 ~1 ~19 minecraft:blackstone
setblock ~2 ~2 ~19 minecraft:blackstone
setblock ~2 ~3 ~19 minecraft:blackstone
setblock ~2 ~0 ~20 minecraft:blackstone
setblock ~2 ~1 ~20 minecraft:blackstone
setblock ~2 ~2 ~20 minecraft:blackstone
setblock ~2 ~3 ~20 minecraft:blackstone
setblock ~2 ~0 ~21 minecraft:blackstone
setblock ~2 ~1 ~21 minecraft:blackstone
setblock ~2 ~2 ~21 minecraft:blackstone
setblock ~2 ~3 ~21 minecraft:blackstone
setblock ~2 ~0 ~22 minecraft:blackstone
setblock ~2 ~1 ~22 minecraft:blackstone
setblock ~2 ~2 ~22 minecraft:blackstone
setblock ~2 ~3 ~22 minecraft:blackstone
setblock ~2 ~0 ~23 minecraft:blackstone
setblock ~2 ~1 ~23 minecraft:blackstone
setblock ~2 ~2 ~23 minecraft:blackstone
setblock ~2 ~3 ~23 minecraft:blackstone
setblock ~3 ~0 ~6 minecraft:blackstone
setblock ~3 ~1 ~6 minecraft:blackstone
setblock ~3 ~2 ~6 minecraft:blackstone
setblock ~3 ~3 ~6 minecraft:blackstone
setblock ~3 ~0 ~7 minecraft:blackstone
setblock ~3 ~1 ~7 minecraft:blackstone
setblock ~3 ~2 ~7 minecraft:blackstone
setblock ~3 ~3 ~7 minecraft:blackstone
setblock ~3 ~0 ~8 minecraft:blackstone
setblock ~3 ~1 ~8 minecraft:blackstone
setblock ~3 ~2 ~8 minecraft:blackstone
setblock ~3 ~3 ~8 minecraft:blackstone
setblock ~3 ~0 ~9 minecraft:blackstone
setblock ~3 ~0 ~10 minecraft:blackstone
setblock ~3 ~0 ~11 minecraft:blackstone
setblock ~3 ~0 ~12 minecraft:blackstone
setblock ~3 ~0 ~13 minecraft:blackstone
setblock ~3 ~0 ~14 minecraft:blackstone
setblock ~3 ~0 ~15 minecraft:blackstone
setblock ~3 ~0 ~16 minecraft:blackstone
setblock ~3 ~0 ~17 minecraft:blackstone
setblock ~3 ~0 ~18 minecraft:blackstone
setblock ~3 ~0 ~19 minecraft:blackstone
setblock ~3 ~0 ~20 minecraft:blackstone
setblock ~3 ~0 ~21 minecraft:blackstone
setblock ~3 ~0 ~22 minecraft:blackstone
setblock ~3 ~1 ~22 minecraft:blackstone
setblock ~3 ~2 ~22 minecraft:blackstone
setblock ~3 ~3 ~22 minecraft:blackstone
setblock ~3 ~0 ~23 minecraft:blackstone
setblock ~3 ~1 ~23 minecraft:blackstone
setblock ~3 ~2 ~23 minecraft:blackstone
setblock ~3 ~3 ~23 minecraft:blackstone
setblock ~3 ~0 ~24 minecraft:blackstone
setblock ~3 ~1 ~24 minecraft:blackstone
setblock ~3 ~2 ~24 minecraft:blackstone
setblock ~3 ~3 ~24 minecraft:blackstone
setblock ~4 ~0 ~5 minecraft:blackstone
setblock ~4 ~1 ~5 minecraft:blackstone
setblock ~4 ~2 ~5 minecraft:blackstone
setblock ~4 ~3 ~5 minecraft:blackstone
setblock ~4 ~0 ~6 minecraft:blackstone
setblock ~4 ~1 ~6 minecraft:blackstone
setblock ~4 ~2 ~6 minecraft:blackstone
setblock ~4 ~3 ~6 minecraft:blackstone
setblock ~4 ~0 ~7 minecraft:blackstone
setblock ~4 ~1 ~7 minecraft:blackstone
setblock ~4 ~2 ~7 minecraft:blackstone
setblock ~4 ~3 ~7 minecraft:blackstone
setblock ~4 ~0 ~8 minecraft:blackstone
setblock ~4 ~0 ~9 minecraft:blackstone
setblock ~4 ~0 ~10 minecraft:blackstone
setblock ~4 ~0 ~11 minecraft:blackstone
setblock ~4 ~0 ~12 minecraft:blackstone
setblock ~4 ~0 ~13 minecraft:blackstone
setblock ~4 ~0 ~14 minecraft:blackstone
setblock ~4 ~0 ~15 minecraft:blackstone
setblock ~4 ~0 ~16 minecraft:blackstone
setblock ~4 ~0 ~17 minecraft:blackstone
setblock ~4 ~0 ~18 minecraft:blackstone
setblock ~4 ~0 ~19 minecraft:blackstone
setblock ~4 ~0 ~20 minecraft:blackstone
setblock ~4 ~0 ~21 minecraft:blackstone
setblock ~4 ~0 ~22 minecraft:blackstone
setblock ~4 ~0 ~23 minecraft:blackstone
setblock ~4 ~1 ~23 minecraft:blackstone
setblock ~4 ~2 ~23 minecraft:blackstone
setblock ~4 ~3 ~23 minecraft:blackstone
setblock ~4 ~0 ~24 minecraft:blackstone
setblock ~4 ~1 ~24 minecraft:blackstone
setblock ~4 ~2 ~24 minecraft:blackstone
setblock ~4 ~3 ~24 minecraft:blackstone
setblock ~4 ~0 ~25 minecraft:blackstone
setblock ~4 ~1 ~25 minecraft:blackstone
setblock ~4 ~2 ~25 minecraft:blackstone
setblock ~4 ~3 ~25 minecraft:blackstone
setblock ~5 ~0 ~4 minecraft:blackstone
setblock ~5 ~1 ~4 minecraft:blackstone
setblock ~5 ~2 ~4 minecraft:blackstone
setblock ~5 ~3 ~4 minecraft:blackstone
setblock ~5 ~0 ~5 minecraft:blackstone
setblock ~5 ~1 ~5 minecraft:blackstone
setblock ~5 ~2 ~5 minecraft:blackstone
setblock ~5 ~3 ~5 minecraft:blackstone
setblock ~5 ~0 ~6 minecraft:blackstone
setblock ~5 ~0 ~7 minecraft:blackstone
setblock ~5 ~0 ~8 minecraft:blackstone
setblock ~5 ~0 ~9 minecraft:blackstone
setblock ~5 ~0 ~10 minecraft:blackstone
setblock ~5 ~0 ~11 minecraft:blackstone
setblock ~5 ~0 ~12 minecraft:blackstone
setblock ~5 ~0 ~13 minecraft:blackstone
setblock ~5 ~0 ~14 minecraft:blackstone
setblock ~5 ~0 ~15 minecraft:blackstone
setblock ~5 ~0 ~16 minecraft:blackstone
setblock ~5 ~0 ~17 minecraft:blackstone
setblock ~5 ~0 ~18 minecraft:blackstone
setblock ~5 ~0 ~19 minecraft:blackstone
setblock ~5 ~0 ~20 minecraft:blackstone
setblock ~5 ~0 ~21 minecraft:blackstone
setblock ~5 ~0 ~22 minecraft:blackstone
setblock ~5 ~0 ~23 minecraft:blackstone
setblock ~5 ~0 ~24 minecraft:blackstone
setblock ~5 ~0 ~25 minecraft:blackstone
setblock ~5 ~1 ~25 minecraft:blackstone
setblock ~5 ~2 ~25 minecraft:blackstone
setblock ~5 ~3 ~25 minecraft:blackstone
setblock ~5 ~0 ~26 minecraft:blackstone
setblock ~5 ~1 ~26 minecraft:blackstone
setblock ~5 ~2 ~26 minecraft:blackstone
setblock ~5 ~3 ~26 minecraft:blackstone
setblock ~6 ~0 ~3 minecraft:blackstone
setblock ~6 ~1 ~3 minecraft:blackstone
setblock ~6 ~2 ~3 minecraft:blackstone
setblock ~6 ~3 ~3 minecraft:blackstone
setblock ~6 ~0 ~4 minecraft:blackstone
setblock ~6 ~1 ~4 minecraft:blackstone
setblock ~6 ~2 ~4 minecraft:blackstone
setblock ~6 ~3 ~4 minecraft:blackstone
setblock ~6 ~0 ~5 minecraft:blackstone
setblock ~6 ~0 ~6 minecraft:blackstone
setblock ~6 ~0 ~7 minecraft:blackstone
setblock ~6 ~0 ~8 minecraft:blackstone
setblock ~6 ~0 ~9 minecraft:blackstone
setblock ~6 ~0 ~10 minecraft:blackstone
setblock ~6 ~0 ~11 minecraft:blackstone
setblock ~6 ~0 ~12 minecraft:blackstone
setblock ~6 ~0 ~13 minecraft:blackstone
setblock ~6 ~0 ~14 minecraft:blackstone
setblock ~6 ~0 ~15 minecraft:blackstone
setblock ~6 ~0 ~16 minecraft:blackstone
setblock ~6 ~0 ~17 minecraft:blackstone
setblock ~6 ~0 ~18 minecraft:blackstone
setblock ~6 ~0 ~19 minecraft:blackstone
setblock ~6 ~0 ~20 minecraft:blackstone
setblock ~6 ~0 ~21 minecraft:blackstone
setblock ~6 ~0 ~22 minecraft:blackstone
setblock ~6 ~0 ~23 minecraft:blackstone
setblock ~6 ~0 ~24 minecraft:blackstone
setblock ~6 ~0 ~25 minecraft:blackstone
setblock ~6 ~0 ~26 minecraft:blackstone
setblock ~6 ~1 ~26 minecraft:blackstone
setblock ~6 ~2 ~26 minecraft:blackstone
setblock ~6 ~3 ~26 minecraft:blackstone
setblock ~6 ~0 ~27 minecraft:blackstone
setblock ~6 ~1 ~27 minecraft:blackstone
setblock ~6 ~2 ~27 minecraft:blackstone
setblock ~6 ~3 ~27 minecraft:blackstone
setblock ~7 ~0 ~2 minecraft:blackstone
setblock ~7 ~1 ~2 minecraft:blackstone
setblock ~7 ~2 ~2 minecraft:blackstone
setblock ~7 ~3 ~2 minecraft:blackstone
setblock ~7 ~0 ~3 minecraft:blackstone
setblock ~7 ~1 ~3 minecraft:blackstone
setblock ~7 ~2 ~3 minecraft:blackstone
setblock ~7 ~3 ~3 minecraft:blackstone
setblock ~7 ~0 ~4 minecraft:blackstone
setblock ~7 ~1 ~4 minecraft:blackstone
setblock ~7 ~2 ~4 minecraft:blackstone
setblock ~7 ~3 ~4 minecraft:blackstone
setblock ~7 ~0 ~5 minecraft:blackstone
setblock ~7 ~0 ~6 minecraft:blackstone
setblock ~7 ~0 ~7 minecraft:blackstone
setblock ~7 ~0 ~8 minecraft:blackstone
setblock ~7 ~0 ~9 minecraft:blackstone
setblock ~7 ~0 ~10 minecraft:blackstone
setblock ~7 ~0 ~11 minecraft:blackstone
setblock ~7 ~0 ~12 minecraft:blackstone
setblock ~7 ~0 ~13 minecraft:blackstone
setblock ~7 ~0 ~14 minecraft:blackstone
setblock ~7 ~0 ~15 minecraft:blackstone
setblock ~7 ~0 ~16 minecraft:blackstone
setblock ~7 ~0 ~17 minecraft:blackstone
setblock ~7 ~0 ~18 minecraft:blackstone
setblock ~7 ~0 ~19 minecraft:blackstone
setblock ~7 ~0 ~20 minecraft:blackstone
setblock ~7 ~0 ~21 minecraft:blackstone
setblock ~7 ~0 ~22 minecraft:blackstone
setblock ~7 ~0 ~23 minecraft:blackstone
setblock ~7 ~0 ~24 minecraft:blackstone
setblock ~7 ~0 ~25 minecraft:blackstone
setblock ~7 ~0 ~26 minecraft:blackstone
setblock ~7 ~1 ~26 minecraft:blackstone
setblock ~7 ~2 ~26 minecraft:blackstone
setblock ~7 ~3 ~26 minecraft:blackstone
setblock ~7 ~0 ~27 minecraft:blackstone
setblock ~7 ~1 ~27 minecraft:blackstone
setblock ~7 ~2 ~27 minecraft:blackstone
setblock ~7 ~3 ~27 minecraft:blackstone
setblock ~7 ~0 ~28 minecraft:blackstone
setblock ~7 ~1 ~28 minecraft:blackstone
setblock ~7 ~2 ~28 minecraft:blackstone
setblock ~7 ~3 ~28 minecraft:blackstone
setblock ~8 ~0 ~2 minecraft:blackstone
setblock ~8 ~1 ~2 minecraft:blackstone
setblock ~8 ~2 ~2 minecraft:blackstone
setblock ~8 ~3 ~2 minecraft:blackstone
setblock ~8 ~0 ~3 minecraft:blackstone
setblock ~8 ~1 ~3 minecraft:blackstone
setblock ~8 ~2 ~3 minecraft:blackstone
setblock ~8 ~3 ~3 minecraft:blackstone
setblock ~8 ~0 ~4 minecraft:blackstone
setblock ~8 ~0 ~5 minecraft:blackstone
setblock ~8 ~0 ~6 minecraft:blackstone
setblock ~8 ~0 ~7 minecraft:blackstone
setblock ~8 ~0 ~8 minecraft:blackstone
setblock ~8 ~0 ~9 minecraft:blackstone
setblock ~8 ~0 ~10 minecraft:blackstone
setblock ~8 ~0 ~11 minecraft:blackstone
setblock ~8 ~0 ~12 minecraft:blackstone
setblock ~8 ~0 ~13 minecraft:blackstone
setblock ~8 ~0 ~14 minecraft:blackstone
setblock ~8 ~0 ~15 minecraft:blackstone
setblock ~8 ~0 ~16 minecraft:blackstone
setblock ~8 ~0 ~17 minecraft:blackstone
setblock ~8 ~0 ~18 minecraft:blackstone
setblock ~8 ~0 ~19 minecraft:blackstone
setblock ~8 ~0 ~20 minecraft:blackstone
setblock ~8 ~0 ~21 minecraft:blackstone
setblock ~8 ~0 ~22 minecraft:blackstone
setblock ~8 ~0 ~23 minecraft:blackstone
setblock ~8 ~0 ~24 minecraft:blackstone
setblock ~8 ~0 ~25 minecraft:blackstone
setblock ~8 ~0 ~26 minecraft:blackstone
setblock ~8 ~0 ~27 minecraft:blackstone
setblock ~8 ~1 ~27 minecraft:blackstone
setblock ~8 ~2 ~27 minecraft:blackstone
setblock ~8 ~3 ~27 minecraft:blackstone
setblock ~8 ~0 ~28 minecraft:blackstone
setblock ~8 ~1 ~28 minecraft:blackstone
setblock ~8 ~2 ~28 minecraft:blackstone
setblock ~8 ~3 ~28 minecraft:blackstone
setblock ~9 ~0 ~1 minecraft:blackstone
setblock ~9 ~1 ~1 minecraft:blackstone
setblock ~9 ~2 ~1 minecraft:blackstone
setblock ~9 ~3 ~1 minecraft:blackstone
setblock ~9 ~0 ~2 minecraft:blackstone
setblock ~9 ~1 ~2 minecraft:blackstone
setblock ~9 ~2 ~2 minecraft:blackstone
setblock ~9 ~3 ~2 minecraft:blackstone
setblock ~9 ~0 ~3 minecraft:blackstone
setblock ~9 ~0 ~4 minecraft:blackstone
setblock ~9 ~0 ~5 minecraft:blackstone
setblock ~9 ~0 ~6 minecraft:blackstone
setblock ~9 ~0 ~7 minecraft:blackstone
setblock ~9 ~0 ~8 minecraft:blackstone
setblock ~9 ~0 ~9 minecraft:blackstone
setblock ~9 ~0 ~10 minecraft:blackstone
setblock ~9 ~0 ~11 minecraft:blackstone
setblock ~9 ~0 ~12 minecraft:blackstone
setblock ~9 ~0 ~13 minecraft:blackstone
setblock ~9 ~0 ~14 minecraft:blackstone
setblock ~9 ~0 ~15 minecraft:blackstone
setblock ~9 ~0 ~16 minecraft:blackstone
setblock ~9 ~0 ~17 minecraft:blackstone
setblock ~9 ~0 ~18 minecraft:blackstone
setblock ~9 ~0 ~19 minecraft:blackstone
setblock ~9 ~0 ~20 minecraft:blackstone
setblock ~9 ~0 ~21 minecraft:blackstone
setblock ~9 ~0 ~22 minecraft:blackstone
setblock ~9 ~0 ~23 minecraft:blackstone
setblock ~9 ~0 ~24 minecraft:blackstone
setblock ~9 ~0 ~25 minecraft:blackstone
setblock ~9 ~0 ~26 minecraft:blackstone
setblock ~9 ~0 ~27 minecraft:blackstone
setblock ~9 ~0 ~28 minecraft:blackstone
setblock ~9 ~1 ~28 minecraft:blackstone
setblock ~9 ~2 ~28 minecraft:blackstone
setblock ~9 ~3 ~28 minecraft:blackstone
setblock ~9 ~0 ~29 minecraft:blackstone
setblock ~9 ~1 ~29 minecraft:blackstone
setblock ~9 ~2 ~29 minecraft:blackstone
setblock ~9 ~3 ~29 minecraft:blackstone
setblock ~10 ~0 ~1 minecraft:blackstone
setblock ~10 ~1 ~1 minecraft:blackstone
setblock ~10 ~2 ~1 minecraft:blackstone
setblock ~10 ~3 ~1 minecraft:blackstone
setblock ~10 ~0 ~2 minecraft:blackstone
setblock ~10 ~1 ~2 minecraft:blackstone
setblock ~10 ~2 ~2 minecraft:blackstone
setblock ~10 ~3 ~2 minecraft:blackstone
setblock ~10 ~0 ~3 minecraft:blackstone
setblock ~10 ~0 ~4 minecraft:blackstone
setblock ~10 ~0 ~5 minecraft:blackstone
setblock ~10 ~0 ~6 minecraft:blackstone
setblock ~10 ~0 ~7 minecraft:blackstone
setblock ~10 ~0 ~8 minecraft:blackstone
setblock ~10 ~0 ~9 minecraft:blackstone
setblock ~10 ~0 ~10 minecraft:blackstone
setblock ~10 ~0 ~11 minecraft:blackstone
setblock ~10 ~0 ~12 minecraft:blackstone
setblock ~10 ~0 ~13 minecraft:blackstone
setblock ~10 ~0 ~14 minecraft:blackstone
setblock ~10 ~0 ~15 minecraft:blackstone
setblock ~10 ~0 ~16 minecraft:blackstone
setblock ~10 ~0 ~17 minecraft:blackstone
setblock ~10 ~0 ~18 minecraft:blackstone
setblock ~10 ~0 ~19 minecraft:blackstone
setblock ~10 ~0 ~20 minecraft:blackstone
setblock ~10 ~0 ~21 minecraft:blackstone
setblock ~10 ~0 ~22 minecraft:blackstone
setblock ~10 ~0 ~23 minecraft:blackstone
setblock ~10 ~0 ~24 minecraft:blackstone
setblock ~10 ~0 ~25 minecraft:blackstone
setblock ~10 ~0 ~26 minecraft:blackstone
setblock ~10 ~0 ~27 minecraft:blackstone
setblock ~10 ~0 ~28 minecraft:blackstone
setblock ~10 ~1 ~28 minecraft:blackstone
setblock ~10 ~2 ~28 minecraft:blackstone
setblock ~10 ~3 ~28 minecraft:blackstone
setblock ~10 ~0 ~29 minecraft:blackstone
setblock ~10 ~1 ~29 minecraft:blackstone
setblock ~10 ~2 ~29 minecraft:blackstone
setblock ~10 ~3 ~29 minecraft:blackstone
setblock ~11 ~0 ~1 minecraft:blackstone
setblock ~11 ~1 ~1 minecraft:blackstone
setblock ~11 ~2 ~1 minecraft:blackstone
setblock ~11 ~3 ~1 minecraft:blackstone
setblock ~11 ~0 ~2 minecraft:blackstone
setblock ~11 ~1 ~2 minecraft:blackstone
setblock ~11 ~2 ~2 minecraft:blackstone
setblock ~11 ~3 ~2 minecraft:blackstone
setblock ~11 ~0 ~3 minecraft:blackstone
setblock ~11 ~0 ~4 minecraft:blackstone
setblock ~11 ~0 ~5 minecraft:blackstone
setblock ~11 ~0 ~6 minecraft:blackstone
setblock ~11 ~0 ~7 minecraft:blackstone
setblock ~11 ~0 ~8 minecraft:blackstone
setblock ~11 ~0 ~9 minecraft:blackstone
setblock ~11 ~0 ~10 minecraft:blackstone
setblock ~11 ~0 ~11 minecraft:red_concrete
setblock ~11 ~0 ~12 minecraft:red_concrete
setblock ~11 ~0 ~13 minecraft:red_concrete
setblock ~11 ~0 ~14 minecraft:red_concrete
setblock ~11 ~0 ~15 minecraft:blackstone
setblock ~11 ~0 ~16 minecraft:white_concrete
setblock ~11 ~0 ~17 minecraft:white_concrete
setblock ~11 ~0 ~18 minecraft:white_concrete
setblock ~11 ~0 ~19 minecraft:white_concrete
setblock ~11 ~0 ~20 minecraft:blackstone
setblock ~11 ~0 ~21 minecraft:blackstone
setblock ~11 ~0 ~22 minecraft:blackstone
setblock ~11 ~0 ~23 minecraft:blackstone
setblock ~11 ~0 ~24 minecraft:blackstone
setblock ~11 ~0 ~25 minecraft:blackstone
setblock ~11 ~0 ~26 minecraft:blackstone
setblock ~11 ~0 ~27 minecraft:blackstone
setblock ~11 ~0 ~28 minecraft:blackstone
setblock ~11 ~1 ~28 minecraft:blackstone
setblock ~11 ~2 ~28 minecraft:blackstone
setblock ~11 ~3 ~28 minecraft:blackstone
setblock ~11 ~0 ~29 minecraft:blackstone
setblock ~11 ~1 ~29 minecraft:blackstone
setblock ~11 ~2 ~29 minecraft:blackstone
setblock ~11 ~3 ~29 minecraft:blackstone
setblock ~12 ~0 ~0 minecraft:blackstone
setblock ~12 ~1 ~0 minecraft:blackstone
setblock ~12 ~2 ~0 minecraft:blackstone
setblock ~12 ~3 ~0 minecraft:blackstone
setblock ~12 ~0 ~1 minecraft:blackstone
setblock ~12 ~1 ~1 minecraft:blackstone
setblock ~12 ~2 ~1 minecraft:blackstone
setblock ~12 ~3 ~1 minecraft:blackstone
setblock ~12 ~0 ~2 minecraft:blackstone
setblock ~12 ~0 ~3 minecraft:blackstone
setblock ~12 ~0 ~4 minecraft:blackstone
setblock ~12 ~0 ~5 minecraft:blackstone
setblock ~12 ~0 ~6 minecraft:blackstone
setblock ~12 ~0 ~7 minecraft:blackstone
setblock ~12 ~0 ~8 minecraft:blackstone
setblock ~12 ~0 ~9 minecraft:blackstone
setblock ~12 ~0 ~10 minecraft:blackstone
setblock ~12 ~0 ~11 minecraft:red_concrete
setblock ~12 ~0 ~12 minecraft:red_concrete
setblock ~12 ~0 ~13 minecraft:red_concrete
setblock ~12 ~0 ~14 minecraft:red_concrete
setblock ~12 ~0 ~15 minecraft:blackstone
setblock ~12 ~0 ~16 minecraft:white_concrete
setblock ~12 ~0 ~17 minecraft:white_concrete
setblock ~12 ~0 ~18 minecraft:white_concrete
setblock ~12 ~0 ~19 minecraft:white_concrete
setblock ~12 ~0 ~20 minecraft:blackstone
setblock ~12 ~0 ~21 minecraft:blackstone
setblock ~12 ~0 ~22 minecraft:blackstone
setblock ~12 ~0 ~23 minecraft:blackstone
setblock ~12 ~0 ~24 minecraft:blackstone
setblock ~12 ~0 ~25 minecraft:blackstone
setblock ~12 ~0 ~26 minecraft:blackstone
setblock ~12 ~0 ~27 minecraft:blackstone
setblock ~12 ~0 ~28 minecraft:blackstone
setblock ~12 ~0 ~29 minecraft:blackstone
setblock ~12 ~1 ~29 minecraft:blackstone
setblock ~12 ~2 ~29 minecraft:blackstone
setblock ~12 ~3 ~29 minecraft:blackstone
setblock ~12 ~0 ~30 minecraft:blackstone
setblock ~12 ~1 ~30 minecraft:blackstone
setblock ~12 ~2 ~30 minecraft:blackstone
setblock ~12 ~3 ~30 minecraft:blackstone
setblock ~13 ~0 ~0 minecraft:blackstone
setblock ~13 ~1 ~0 minecraft:blackstone
setblock ~13 ~2 ~0 minecraft:blackstone
setblock ~13 ~3 ~0 minecraft:blackstone
setblock ~13 ~0 ~1 minecraft:blackstone
setblock ~13 ~1 ~1 minecraft:blackstone
setblock ~13 ~2 ~1 minecraft:blackstone
setblock ~13 ~3 ~1 minecraft:blackstone
setblock ~13 ~0 ~2 minecraft:blackstone
setblock ~13 ~0 ~3 minecraft:blackstone
setblock ~13 ~0 ~4 minecraft:blackstone
setblock ~13 ~0 ~5 minecraft:blackstone
setblock ~13 ~0 ~6 minecraft:blackstone
setblock ~13 ~0 ~7 minecraft:blackstone
setblock ~13 ~0 ~8 minecraft:blackstone
setblock ~13 ~0 ~9 minecraft:blackstone
setblock ~13 ~0 ~10 minecraft:blackstone
setblock ~13 ~0 ~11 minecraft:red_concrete
setblock ~13 ~0 ~12 minecraft:red_concrete
setblock ~13 ~0 ~13 minecraft:red_concrete
setblock ~13 ~0 ~14 minecraft:red_concrete
setblock ~13 ~0 ~15 minecraft:blackstone
setblock ~13 ~0 ~16 minecraft:white_concrete
setblock ~13 ~0 ~17 minecraft:white_concrete
setblock ~13 ~0 ~18 minecraft:white_concrete
setblock ~13 ~0 ~19 minecraft:white_concrete
setblock ~13 ~0 ~20 minecraft:blackstone
setblock ~13 ~0 ~21 minecraft:blackstone
setblock ~13 ~0 ~22 minecraft:blackstone
setblock ~13 ~0 ~23 minecraft:blackstone
setblock ~13 ~0 ~24 minecraft:blackstone
setblock ~13 ~0 ~25 minecraft:blackstone
setblock ~13 ~0 ~26 minecraft:blackstone
setblock ~13 ~0 ~27 minecraft:blackstone
setblock ~13 ~0 ~28 minecraft:blackstone
setblock ~13 ~0 ~29 minecraft:blackstone
setblock ~13 ~1 ~29 minecraft:blackstone
setblock ~13 ~2 ~29 minecraft:blackstone
setblock ~13 ~3 ~29 minecraft:blackstone
setblock ~13 ~0 ~30 minecraft:blackstone
setblock ~13 ~1 ~30 minecraft:blackstone
setblock ~13 ~2 ~30 minecraft:blackstone
setblock ~13 ~3 ~30 minecraft:blackstone
setblock ~14 ~0 ~0 minecraft:blackstone
setblock ~14 ~1 ~0 minecraft:blackstone
setblock ~14 ~2 ~0 minecraft:blackstone
setblock ~14 ~3 ~0 minecraft:blackstone
setblock ~14 ~0 ~1 minecraft:blackstone
setblock ~14 ~1 ~1 minecraft:blackstone
setblock ~14 ~2 ~1 minecraft:blackstone
setblock ~14 ~3 ~1 minecraft:blackstone
setblock ~14 ~0 ~2 minecraft:blackstone
setblock ~14 ~0 ~3 minecraft:blackstone
setblock ~14 ~0 ~4 minecraft:blackstone
setblock ~14 ~0 ~5 minecraft:blackstone
setblock ~14 ~0 ~6 minecraft:blackstone
setblock ~14 ~0 ~7 minecraft:blackstone
setblock ~14 ~0 ~8 minecraft:blackstone
setblock ~14 ~0 ~9 minecraft:blackstone
setblock ~14 ~0 ~10 minecraft:blackstone
setblock ~14 ~0 ~11 minecraft:red_concrete
setblock ~14 ~0 ~12 minecraft:red_concrete
setblock ~14 ~0 ~13 minecraft:red_concrete
setblock ~14 ~0 ~14 minecraft:blackstone
setblock ~14 ~0 ~15 minecraft:blackstone
setblock ~14 ~0 ~16 minecraft:blackstone
setblock ~14 ~0 ~17 minecraft:white_concrete
setblock ~14 ~0 ~18 minecraft:white_concrete
setblock ~14 ~0 ~19 minecraft:white_concrete
setblock ~14 ~0 ~20 minecraft:blackstone
setblock ~14 ~0 ~21 minecraft:blackstone
setblock ~14 ~0 ~22 minecraft:blackstone
setblock ~14 ~0 ~23 minecraft:blackstone
setblock ~14 ~0 ~24 minecraft:blackstone
setblock ~14 ~0 ~25 minecraft:blackstone
setblock ~14 ~0 ~26 minecraft:blackstone
setblock ~14 ~0 ~27 minecraft:blackstone
setblock ~14 ~0 ~28 minecraft:blackstone
setblock ~14 ~0 ~29 minecraft:blackstone
setblock ~14 ~1 ~29 minecraft:blackstone
setblock ~14 ~2 ~29 minecraft:blackstone
setblock ~14 ~3 ~29 minecraft:blackstone
setblock ~14 ~0 ~30 minecraft:blackstone
setblock ~14 ~1 ~30 minecraft:blackstone
setblock ~14 ~2 ~30 minecraft:blackstone
setblock ~14 ~3 ~30 minecraft:blackstone
setblock ~15 ~0 ~0 minecraft:blackstone
setblock ~15 ~1 ~0 minecraft:blackstone
setblock ~15 ~2 ~0 minecraft:blackstone
setblock ~15 ~3 ~0 minecraft:blackstone
setblock ~15 ~0 ~1 minecraft:blackstone
setblock ~15 ~1 ~1 minecraft:blackstone
setblock ~15 ~2 ~1 minecraft:blackstone
setblock ~15 ~3 ~1 minecraft:blackstone
setblock ~15 ~0 ~2 minecraft:blackstone
setblock ~15 ~0 ~3 minecraft:blackstone
setblock ~15 ~0 ~4 minecraft:blackstone
setblock ~15 ~0 ~5 minecraft:blackstone
setblock ~15 ~0 ~6 minecraft:blackstone
setblock ~15 ~0 ~7 minecraft:blackstone
setblock ~15 ~0 ~8 minecraft:blackstone
setblock ~15 ~0 ~9 minecraft:blackstone
setblock ~15 ~0 ~10 minecraft:blackstone
setblock ~15 ~0 ~11 minecraft:red_concrete
setblock ~15 ~0 ~12 minecraft:red_concrete
setblock ~15 ~0 ~13 minecraft:red_concrete
setblock ~15 ~0 ~14 minecraft:blackstone
setblock ~15 ~0 ~15 minecraft:sea_lantern
setblock ~15 ~0 ~16 minecraft:blackstone
setblock ~15 ~0 ~17 minecraft:white_concrete
setblock ~15 ~0 ~18 minecraft:white_concrete
setblock ~15 ~0 ~19 minecraft:white_concrete
setblock ~15 ~0 ~20 minecraft:blackstone
setblock ~15 ~0 ~21 minecraft:blackstone
setblock ~15 ~0 ~22 minecraft:blackstone
setblock ~15 ~0 ~23 minecraft:blackstone
setblock ~15 ~0 ~24 minecraft:blackstone
setblock ~15 ~0 ~25 minecraft:blackstone
setblock ~15 ~0 ~26 minecraft:blackstone
setblock ~15 ~0 ~27 minecraft:blackstone
setblock ~15 ~0 ~28 minecraft:blackstone
setblock ~15 ~0 ~29 minecraft:blackstone
setblock ~15 ~1 ~29 minecraft:blackstone
setblock ~15 ~2 ~29 minecraft:blackstone
setblock ~15 ~3 ~29 minecraft:blackstone
setblock ~15 ~0 ~30 minecraft:blackstone
setblock ~15 ~1 ~30 minecraft:blackstone
setblock ~15 ~2 ~30 minecraft:blackstone
setblock ~15 ~3 ~30 minecraft:blackstone
setblock ~16 ~0 ~0 minecraft:blackstone
setblock ~16 ~1 ~0 minecraft:blackstone
setblock ~16 ~2 ~0 minecraft:blackstone
setblock ~16 ~3 ~0 minecraft:blackstone
setblock ~16 ~0 ~1 minecraft:blackstone
setblock ~16 ~1 ~1 minecraft:blackstone
setblock ~16 ~2 ~1 minecraft:blackstone
setblock ~16 ~3 ~1 minecraft:blackstone
setblock ~16 ~0 ~2 minecraft:blackstone
setblock ~16 ~0 ~3 minecraft:blackstone
setblock ~16 ~0 ~4 minecraft:blackstone
setblock ~16 ~0 ~5 minecraft:blackstone
setblock ~16 ~0 ~6 minecraft:blackstone
setblock ~16 ~0 ~7 minecraft:blackstone
setblock ~16 ~0 ~8 minecraft:blackstone
setblock ~16 ~0 ~9 minecraft:blackstone
setblock ~16 ~0 ~10 minecraft:blackstone
setblock ~16 ~0 ~11 minecraft:red_concrete
setblock ~16 ~0 ~12 minecraft:red_concrete
setblock ~16 ~0 ~13 minecraft:red_concrete
setblock ~16 ~0 ~14 minecraft:blackstone
setblock ~16 ~0 ~15 minecraft:blackstone
setblock ~16 ~0 ~16 minecraft:blackstone
setblock ~16 ~0 ~17 minecraft:white_concrete
setblock ~16 ~0 ~18 minecraft:white_concrete
setblock ~16 ~0 ~19 minecraft:white_concrete
setblock ~16 ~0 ~20 minecraft:blackstone
setblock ~16 ~0 ~21 minecraft:blackstone
setblock ~16 ~0 ~22 minecraft:blackstone
setblock ~16 ~0 ~23 minecraft:blackstone
setblock ~16 ~0 ~24 minecraft:blackstone
setblock ~16 ~0 ~25 minecraft:blackstone
setblock ~16 ~0 ~26 minecraft:blackstone
setblock ~16 ~0 ~27 minecraft:blackstone
setblock ~16 ~0 ~28 minecraft:blackstone
setblock ~16 ~0 ~29 minecraft:blackstone
setblock ~16 ~1 ~29 minecraft:blackstone
setblock ~16 ~2 ~29 minecraft:blackstone
setblock ~16 ~3 ~29 minecraft:blackstone
setblock ~16 ~0 ~30 minecraft:blackstone
setblock ~16 ~1 ~30 minecraft:blackstone
setblock ~16 ~2 ~30 minecraft:blackstone
setblock ~16 ~3 ~30 minecraft:blackstone
setblock ~17 ~0 ~0 minecraft:blackstone
setblock ~17 ~1 ~0 minecraft:blackstone
setblock ~17 ~2 ~0 minecraft:blackstone
setblock ~17 ~3 ~0 minecraft:blackstone
setblock ~17 ~0 ~1 minecraft:blackstone
setblock ~17 ~1 ~1 minecraft:blackstone
setblock ~17 ~2 ~1 minecraft:blackstone
setblock ~17 ~3 ~1 minecraft:blackstone
setblock ~17 ~0 ~2 minecraft:blackstone
setblock ~17 ~0 ~3 minecraft:blackstone
setblock ~17 ~0 ~4 minecraft:blackstone
setblock ~17 ~0 ~5 minecraft:blackstone
setblock ~17 ~0 ~6 minecraft:blackstone
setblock ~17 ~0 ~7 minecraft:blackstone
setblock ~17 ~0 ~8 minecraft:blackstone
setblock ~17 ~0 ~9 minecraft:blackstone
setblock ~17 ~0 ~10 minecraft:blackstone
setblock ~17 ~0 ~11 minecraft:red_concrete
setblock ~17 ~0 ~12 minecraft:red_concrete
setblock ~17 ~0 ~13 minecraft:red_concrete
setblock ~17 ~0 ~14 minecraft:red_concrete
setblock ~17 ~0 ~15 minecraft:blackstone
setblock ~17 ~0 ~16 minecraft:white_concrete
setblock ~17 ~0 ~17 minecraft:white_concrete
setblock ~17 ~0 ~18 minecraft:white_concrete
setblock ~17 ~0 ~19 minecraft:white_concrete
setblock ~17 ~0 ~20 minecraft:blackstone
setblock ~17 ~0 ~21 minecraft:blackstone
setblock ~17 ~0 ~22 minecraft:blackstone
setblock ~17 ~0 ~23 minecraft:blackstone
setblock ~17 ~0 ~24 minecraft:blackstone
setblock ~17 ~0 ~25 minecraft:blackstone
setblock ~17 ~0 ~26 minecraft:blackstone
setblock ~17 ~0 ~27 minecraft:blackstone
setblock ~17 ~0 ~28 minecraft:blackstone
setblock ~17 ~0 ~29 minecraft:blackstone
setblock ~17 ~1 ~29 minecraft:blackstone
setblock ~17 ~2 ~29 minecraft:blackstone
setblock ~17 ~3 ~29 minecraft:blackstone
setblock ~17 ~0 ~30 minecraft:blackstone
setblock ~17 ~1 ~30 minecraft:blackstone
setblock ~17 ~2 ~30 minecraft:blackstone
setblock ~17 ~3 ~30 minecraft:blackstone
setblock ~18 ~0 ~0 minecraft:blackstone
setblock ~18 ~1 ~0 minecraft:blackstone
setblock ~18 ~2 ~0 minecraft:blackstone
setblock ~18 ~3 ~0 minecraft:blackstone
setblock ~18 ~0 ~1 minecraft:blackstone
setblock ~18 ~1 ~1 minecraft:blackstone
setblock ~18 ~2 ~1 minecraft:blackstone
setblock ~18 ~3 ~1 minecraft:blackstone
setblock ~18 ~0 ~2 minecraft:blackstone
setblock ~18 ~0 ~3 minecraft:blackstone
setblock ~18 ~0 ~4 minecraft:blackstone
setblock ~18 ~0 ~5 minecraft:blackstone
setblock ~18 ~0 ~6 minecraft:blackstone
setblock ~18 ~0 ~7 minecraft:blackstone
setblock ~18 ~0 ~8 minecraft:blackstone
setblock ~18 ~0 ~9 minecraft:blackstone
setblock ~18 ~0 ~10 minecraft:blackstone
setblock ~18 ~0 ~11 minecraft:red_concrete
setblock ~18 ~0 ~12 minecraft:red_concrete
setblock ~18 ~0 ~13 minecraft:red_concrete
setblock ~18 ~0 ~14 minecraft:red_concrete
setblock ~18 ~0 ~15 minecraft:blackstone
setblock ~18 ~0 ~16 minecraft:white_concrete
setblock ~18 ~0 ~17 minecraft:white_concrete
setblock ~18 ~0 ~18 minecraft:white_concrete
setblock ~18 ~0 ~19 minecraft:white_concrete
setblock ~18 ~0 ~20 minecraft:blackstone
setblock ~18 ~0 ~21 minecraft:blackstone
setblock ~18 ~0 ~22 minecraft:blackstone
setblock ~18 ~0 ~23 minecraft:blackstone
setblock ~18 ~0 ~24 minecraft:blackstone
setblock ~18 ~0 ~25 minecraft:blackstone
setblock ~18 ~0 ~26 minecraft:blackstone
setblock ~18 ~0 ~27 minecraft:blackstone
setblock ~18 ~0 ~28 minecraft:blackstone
setblock ~18 ~0 ~29 minecraft:blackstone
setblock ~18 ~1 ~29 minecraft:blackstone
setblock ~18 ~2 ~29 minecraft:blackstone
setblock ~18 ~3 ~29 minecraft:blackstone
setblock ~18 ~0 ~30 minecraft:blackstone
setblock ~18 ~1 ~30 minecraft:blackstone
setblock ~18 ~2 ~30 minecraft:blackstone
setblock ~18 ~3 ~30 minecraft:blackstone
setblock ~19 ~0 ~1 minecraft:blackstone
setblock ~19 ~1 ~1 minecraft:blackstone
setblock ~19 ~2 ~1 minecraft:blackstone
setblock ~19 ~3 ~1 minecraft:blackstone
setblock ~19 ~0 ~2 minecraft:blackstone
setblock ~19 ~1 ~2 minecraft:blackstone
setblock ~19 ~2 ~2 minecraft:blackstone
setblock ~19 ~3 ~2 minecraft:blackstone
setblock ~19 ~0 ~3 minecraft:blackstone
setblock ~19 ~0 ~4 minecraft:blackstone
setblock ~19 ~0 ~5 minecraft:blackstone
setblock ~19 ~0 ~6 minecraft:blackstone
setblock ~19 ~0 ~7 minecraft:blackstone
setblock ~19 ~0 ~8 minecraft:blackstone
setblock ~19 ~0 ~9 minecraft:blackstone
setblock ~19 ~0 ~10 minecraft:blackstone
setblock ~19 ~0 ~11 minecraft:red_concrete
setblock ~19 ~0 ~12 minecraft:red_concrete
setblock ~19 ~0 ~13 minecraft:red_concrete
setblock ~19 ~0 ~14 minecraft:red_concrete
setblock ~19 ~0 ~15 minecraft:blackstone
setblock ~19 ~0 ~16 minecraft:white_concrete
setblock ~19 ~0 ~17 minecraft:white_concrete
setblock ~19 ~0 ~18 minecraft:white_concrete
setblock ~19 ~0 ~19 minecraft:white_concrete
setblock ~19 ~0 ~20 minecraft:blackstone
setblock ~19 ~0 ~21 minecraft:blackstone
setblock ~19 ~0 ~22 minecraft:blackstone
setblock ~19 ~0 ~23 minecraft:blackstone
setblock ~19 ~0 ~24 minecraft:blackstone
setblock ~19 ~0 ~25 minecraft:blackstone
setblock ~19 ~0 ~26 minecraft:blackstone
setblock ~19 ~0 ~27 minecraft:blackstone
setblock ~19 ~0 ~28 minecraft:blackstone
setblock ~19 ~1 ~28 minecraft:blackstone
setblock ~19 ~2 ~28 minecraft:blackstone
setblock ~19 ~3 ~28 minecraft:blackstone
setblock ~19 ~0 ~29 minecraft:blackstone
setblock ~19 ~1 ~29 minecraft:blackstone
setblock ~19 ~2 ~29 minecraft:blackstone
setblock ~19 ~3 ~29 minecraft:blackstone
setblock ~20 ~0 ~1 minecraft:blackstone
setblock ~20 ~1 ~1 minecraft:blackstone
setblock ~20 ~2 ~1 minecraft:blackstone
setblock ~20 ~3 ~1 minecraft:blackstone
setblock ~20 ~0 ~2 minecraft:blackstone
setblock ~20 ~1 ~2 minecraft:blackstone
setblock ~20 ~2 ~2 minecraft:blackstone
setblock ~20 ~3 ~2 minecraft:blackstone
setblock ~20 ~0 ~3 minecraft:blackstone
setblock ~20 ~0 ~4 minecraft:blackstone
setblock ~20 ~0 ~5 minecraft:blackstone
setblock ~20 ~0 ~6 minecraft:blackstone
setblock ~20 ~0 ~7 minecraft:blackstone
setblock ~20 ~0 ~8 minecraft:blackstone
setblock ~20 ~0 ~9 minecraft:blackstone
setblock ~20 ~0 ~10 minecraft:blackstone
setblock ~20 ~0 ~11 minecraft:blackstone
setblock ~20 ~0 ~12 minecraft:blackstone
setblock ~20 ~0 ~13 minecraft:blackstone
setblock ~20 ~0 ~14 minecraft:blackstone
setblock ~20 ~0 ~15 minecraft:blackstone
setblock ~20 ~0 ~16 minecraft:blackstone
setblock ~20 ~0 ~17 minecraft:blackstone
setblock ~20 ~0 ~18 minecraft:blackstone
setblock ~20 ~0 ~19 minecraft:blackstone
setblock ~20 ~0 ~20 minecraft:blackstone
setblock ~20 ~0 ~21 minecraft:blackstone
setblock ~20 ~0 ~22 minecraft:blackstone
setblock ~20 ~0 ~23 minecraft:blackstone
setblock ~20 ~0 ~24 minecraft:blackstone
setblock ~20 ~0 ~25 minecraft:blackstone
setblock ~20 ~0 ~26 minecraft:blackstone
setblock ~20 ~0 ~27 minecraft:blackstone
setblock ~20 ~0 ~28 minecraft:blackstone
setblock ~20 ~1 ~28 minecraft:blackstone
setblock ~20 ~2 ~28 minecraft:blackstone
setblock ~20 ~3 ~28 minecraft:blackstone
setblock ~20 ~0 ~29 minecraft:blackstone
setblock ~20 ~1 ~29 minecraft:blackstone
setblock ~20 ~2 ~29 minecraft:blackstone
setblock ~20 ~3 ~29 minecraft:blackstone
setblock ~21 ~0 ~1 minecraft:blackstone
setblock ~21 ~1 ~1 minecraft:blackstone
setblock ~21 ~2 ~1 minecraft:blackstone
setblock ~21 ~3 ~1 minecraft:blackstone
setblock ~21 ~0 ~2 minecraft:blackstone
setblock ~21 ~1 ~2 minecraft:blackstone
setblock ~21 ~2 ~2 minecraft:blackstone
setblock ~21 ~3 ~2 minecraft:blackstone
setblock ~21 ~0 ~3 minecraft:blackstone
setblock ~21 ~0 ~4 minecraft:blackstone
setblock ~21 ~0 ~5 minecraft:blackstone
setblock ~21 ~0 ~6 minecraft:blackstone
setblock ~21 ~0 ~7 minecraft:blackstone
setblock ~21 ~0 ~8 minecraft:blackstone
setblock ~21 ~0 ~9 minecraft:blackstone
setblock ~21 ~0 ~10 minecraft:blackstone
setblock ~21 ~0 ~11 minecraft:blackstone
setblock ~21 ~0 ~12 minecraft:blackstone
setblock ~21 ~0 ~13 minecraft:blackstone
setblock ~21 ~0 ~14 minecraft:blackstone
setblock ~21 ~0 ~15 minecraft:blackstone
setblock ~21 ~0 ~16 minecraft:blackstone
setblock ~21 ~0 ~17 minecraft:blackstone
setblock ~21 ~0 ~18 minecraft:blackstone
setblock ~21 ~0 ~19 minecraft:blackstone
setblock ~21 ~0 ~20 minecraft:blackstone
setblock ~21 ~0 ~21 minecraft:blackstone
setblock ~21 ~0 ~22 minecraft:blackstone
setblock ~21 ~0 ~23 minecraft:blackstone
setblock ~21 ~0 ~24 minecraft:blackstone
setblock ~21 ~0 ~25 minecraft:blackstone
setblock ~21 ~0 ~26 minecraft:blackstone
setblock ~21 ~0 ~27 minecraft:blackstone
setblock ~21 ~0 ~28 minecraft:blackstone
setblock ~21 ~1 ~28 minecraft:blackstone
setblock ~21 ~2 ~28 minecraft:blackstone
setblock ~21 ~3 ~28 minecraft:blackstone
setblock ~21 ~0 ~29 minecraft:blackstone
setblock ~21 ~1 ~29 minecraft:blackstone
setblock ~21 ~2 ~29 minecraft:blackstone
setblock ~21 ~3 ~29 minecraft:blackstone
setblock ~22 ~0 ~2 minecraft:blackstone
setblock ~22 ~1 ~2 minecraft:blackstone
setblock ~22 ~2 ~2 minecraft:blackstone
setblock ~22 ~3 ~2 minecraft:blackstone
setblock ~22 ~0 ~3 minecraft:blackstone
setblock ~22 ~1 ~3 minecraft:blackstone
setblock ~22 ~2 ~3 minecraft:blackstone
setblock ~22 ~3 ~3 minecraft:blackstone
setblock ~22 ~0 ~4 minecraft:blackstone
setblock ~22 ~0 ~5 minecraft:blackstone
setblock ~22 ~0 ~6 minecraft:blackstone
setblock ~22 ~0 ~7 minecraft:blackstone
setblock ~22 ~0 ~8 minecraft:blackstone
setblock ~22 ~0 ~9 minecraft:blackstone
setblock ~22 ~0 ~10 minecraft:blackstone
setblock ~22 ~0 ~11 minecraft:blackstone
setblock ~22 ~0 ~12 minecraft:blackstone
setblock ~22 ~0 ~13 minecraft:blackstone
setblock ~22 ~0 ~14 minecraft:blackstone
setblock ~22 ~0 ~15 minecraft:blackstone
setblock ~22 ~0 ~16 minecraft:blackstone
setblock ~22 ~0 ~17 minecraft:blackstone
setblock ~22 ~0 ~18 minecraft:blackstone
setblock ~22 ~0 ~19 minecraft:blackstone
setblock ~22 ~0 ~20 minecraft:blackstone
setblock ~22 ~0 ~21 minecraft:blackstone
setblock ~22 ~0 ~22 minecraft:blackstone
setblock ~22 ~0 ~23 minecraft:blackstone
setblock ~22 ~0 ~24 minecraft:blackstone
setblock ~22 ~0 ~25 minecraft:blackstone
setblock ~22 ~0 ~26 minecraft:blackstone
setblock ~22 ~0 ~27 minecraft:blackstone
setblock ~22 ~1 ~27 minecraft:blackstone
setblock ~22 ~2 ~27 minecraft:blackstone
setblock ~22 ~3 ~27 minecraft:blackstone
setblock ~22 ~0 ~28 minecraft:blackstone
setblock ~22 ~1 ~28 minecraft:blackstone
setblock ~22 ~2 ~28 minecraft:blackstone
setblock ~22 ~3 ~28 minecraft:blackstone
setblock ~23 ~0 ~2 minecraft:blackstone
setblock ~23 ~1 ~2 minecraft:blackstone
setblock ~23 ~2 ~2 minecraft:blackstone
setblock ~23 ~3 ~2 minecraft:blackstone
setblock ~23 ~0 ~3 minecraft:blackstone
setblock ~23 ~1 ~3 minecraft:blackstone
setblock ~23 ~2 ~3 minecraft:blackstone
setblock ~23 ~3 ~3 minecraft:blackstone
setblock ~23 ~0 ~4 minecraft:blackstone
setblock ~23 ~1 ~4 minecraft:blackstone
setblock ~23 ~2 ~4 minecraft:blackstone
setblock ~23 ~3 ~4 minecraft:blackstone
setblock ~23 ~0 ~5 minecraft:blackstone
setblock ~23 ~0 ~6 minecraft:blackstone
setblock ~23 ~0 ~7 minecraft:blackstone
setblock ~23 ~0 ~8 minecraft:blackstone
setblock ~23 ~0 ~9 minecraft:blackstone
setblock ~23 ~0 ~10 minecraft:blackstone
setblock ~23 ~0 ~11 minecraft:blackstone
setblock ~23 ~0 ~12 minecraft:blackstone
setblock ~23 ~0 ~13 minecraft:blackstone
setblock ~23 ~0 ~14 minecraft:blackstone
setblock ~23 ~0 ~15 minecraft:blackstone
setblock ~23 ~0 ~16 minecraft:blackstone
setblock ~23 ~0 ~17 minecraft:blackstone
setblock ~23 ~0 ~18 minecraft:blackstone
setblock ~23 ~0 ~19 minecraft:blackstone
setblock ~23 ~0 ~20 minecraft:blackstone
setblock ~23 ~0 ~21 minecraft:blackstone
setblock ~23 ~0 ~22 minecraft:blackstone
setblock ~23 ~0 ~23 minecraft:blackstone
setblock ~23 ~0 ~24 minecraft:blackstone
setblock ~23 ~0 ~25 minecraft:blackstone
setblock ~23 ~0 ~26 minecraft:blackstone
setblock ~23 ~1 ~26 minecraft:blackstone
setblock ~23 ~2 ~26 minecraft:blackstone
setblock ~23 ~3 ~26 minecraft:blackstone
setblock ~23 ~0 ~27 minecraft:blackstone
setblock ~23 ~1 ~27 minecraft:blackstone
setblock ~23 ~2 ~27 minecraft:blackstone
setblock ~23 ~3 ~27 minecraft:blackstone
setblock ~23 ~0 ~28 minecraft:blackstone
setblock ~23 ~1 ~28 minecraft:blackstone
setblock ~23 ~2 ~28 minecraft:blackstone
setblock ~23 ~3 ~28 minecraft:blackstone
setblock ~24 ~0 ~3 minecraft:blackstone
setblock ~24 ~1 ~3 minecraft:blackstone
setblock ~24 ~2 ~3 minecraft:blackstone
setblock ~24 ~3 ~3 minecraft:blackstone
setblock ~24 ~0 ~4 minecraft:blackstone
setblock ~24 ~1 ~4 minecraft:blackstone
setblock ~24 ~2 ~4 minecraft:blackstone
setblock ~24 ~3 ~4 minecraft:blackstone
setblock ~24 ~0 ~5 minecraft:blackstone
setblock ~24 ~0 ~6 minecraft:blackstone
setblock ~24 ~0 ~7 minecraft:blackstone
setblock ~24 ~0 ~8 minecraft:blackstone
setblock ~24 ~0 ~9 minecraft:blackstone
setblock ~24 ~0 ~10 minecraft:blackstone
setblock ~24 ~0 ~11 minecraft:blackstone
setblock ~24 ~0 ~12 minecraft:blackstone
setblock ~24 ~0 ~13 minecraft:blackstone
setblock ~24 ~0 ~14 minecraft:blackstone
setblock ~24 ~0 ~15 minecraft:blackstone
setblock ~24 ~0 ~16 minecraft:blackstone
setblock ~24 ~0 ~17 minecraft:blackstone
setblock ~24 ~0 ~18 minecraft:blackstone
setblock ~24 ~0 ~19 minecraft:blackstone
setblock ~24 ~0 ~20 minecraft:blackstone
setblock ~24 ~0 ~21 minecraft:blackstone
setblock ~24 ~0 ~22 minecraft:blackstone
setblock ~24 ~0 ~23 minecraft:blackstone
setblock ~24 ~0 ~24 minecraft:blackstone
setblock ~24 ~0 ~25 minecraft:blackstone
setblock ~24 ~0 ~26 minecraft:blackstone
setblock ~24 ~1 ~26 minecraft:blackstone
setblock ~24 ~2 ~26 minecraft:blackstone
setblock ~24 ~3 ~26 minecraft:blackstone
setblock ~24 ~0 ~27 minecraft:blackstone
setblock ~24 ~1 ~27 minecraft:blackstone
setblock ~24 ~2 ~27 minecraft:blackstone
setblock ~24 ~3 ~27 minecraft:blackstone
setblock ~25 ~0 ~4 minecraft:blackstone
setblock ~25 ~1 ~4 minecraft:blackstone
setblock ~25 ~2 ~4 minecraft:blackstone
setblock ~25 ~3 ~4 minecraft:blackstone
setblock ~25 ~0 ~5 minecraft:blackstone
setblock ~25 ~1 ~5 minecraft:blackstone
setblock ~25 ~2 ~5 minecraft:blackstone
setblock ~25 ~3 ~5 minecraft:blackstone
setblock ~25 ~0 ~6 minecraft:blackstone
setblock ~25 ~0 ~7 minecraft:blackstone
setblock ~25 ~0 ~8 minecraft:blackstone
setblock ~25 ~0 ~9 minecraft:blackstone
setblock ~25 ~0 ~10 minecraft:blackstone
setblock ~25 ~0 ~11 minecraft:blackstone
setblock ~25 ~0 ~12 minecraft:blackstone
setblock ~25 ~0 ~13 minecraft:blackstone
setblock ~25 ~0 ~14 minecraft:blackstone
setblock ~25 ~0 ~15 minecraft:blackstone
setblock ~25 ~0 ~16 minecraft:blackstone
setblock ~25 ~0 ~17 minecraft:blackstone
setblock ~25 ~0 ~18 minecraft:blackstone
setblock ~25 ~0 ~19 minecraft:blackstone
setblock ~25 ~0 ~20 minecraft:blackstone
setblock ~25 ~0 ~21 minecraft:blackstone
setblock ~25 ~0 ~22 minecraft:blackstone
setblock ~25 ~0 ~23 minecraft:blackstone
setblock ~25 ~0 ~24 minecraft:blackstone
setblock ~25 ~0 ~25 minecraft:blackstone
setblock ~25 ~1 ~25 minecraft:blackstone
setblock ~25 ~2 ~25 minecraft:blackstone
setblock ~25 ~3 ~25 minecraft:blackstone
setblock ~25 ~0 ~26 minecraft:blackstone
setblock ~25 ~1 ~26 minecraft:blackstone
setblock ~25 ~2 ~26 minecraft:blackstone
setblock ~25 ~3 ~26 minecraft:blackstone
setblock ~26 ~0 ~5 minecraft:blackstone
setblock ~26 ~1 ~5 minecraft:blackstone
setblock ~26 ~2 ~5 minecraft:blackstone
setblock ~26 ~3 ~5 minecraft:blackstone
setblock ~26 ~0 ~6 minecraft:blackstone
setblock ~26 ~1 ~6 minecraft:blackstone
setblock ~26 ~2 ~6 minecraft:blackstone
setblock ~26 ~3 ~6 minecraft:blackstone
setblock ~26 ~0 ~7 minecraft:blackstone
setblock ~26 ~1 ~7 minecraft:blackstone
setblock ~26 ~2 ~7 minecraft:blackstone
setblock ~26 ~3 ~7 minecraft:blackstone
setblock ~26 ~0 ~8 minecraft:blackstone
setblock ~26 ~0 ~9 minecraft:blackstone
setblock ~26 ~0 ~10 minecraft:blackstone
setblock ~26 ~0 ~11 minecraft:blackstone
setblock ~26 ~0 ~12 minecraft:blackstone
setblock ~26 ~0 ~13 minecraft:blackstone
setblock ~26 ~0 ~14 minecraft:blackstone
setblock ~26 ~0 ~15 minecraft:blackstone
setblock ~26 ~0 ~16 minecraft:blackstone
setblock ~26 ~0 ~17 minecraft:blackstone
setblock ~26 ~0 ~18 minecraft:blackstone
setblock ~26 ~0 ~19 minecraft:blackstone
setblock ~26 ~0 ~20 minecraft:blackstone
setblock ~26 ~0 ~21 minecraft:blackstone
setblock ~26 ~0 ~22 minecraft:blackstone
setblock ~26 ~0 ~23 minecraft:blackstone
setblock ~26 ~1 ~23 minecraft:blackstone
setblock ~26 ~2 ~23 minecraft:blackstone
setblock ~26 ~3 ~23 minecraft:blackstone
setblock ~26 ~0 ~24 minecraft:blackstone
setblock ~26 ~1 ~24 minecraft:blackstone
setblock ~26 ~2 ~24 minecraft:blackstone
setblock ~26 ~3 ~24 minecraft:blackstone
setblock ~26 ~0 ~25 minecraft:blackstone
setblock ~26 ~1 ~25 minecraft:blackstone
setblock ~26 ~2 ~25 minecraft:blackstone
setblock ~26 ~3 ~25 minecraft:blackstone
setblock ~27 ~0 ~6 minecraft:blackstone
setblock ~27 ~1 ~6 minecraft:blackstone
setblock ~27 ~2 ~6 minecraft:blackstone
setblock ~27 ~3 ~6 minecraft:blackstone
setblock ~27 ~0 ~7 minecraft:blackstone
setblock ~27 ~1 ~7 minecraft:blackstone
setblock ~27 ~2 ~7 minecraft:blackstone
setblock ~27 ~3 ~7 minecraft:blackstone
setblock ~27 ~0 ~8 minecraft:blackstone
setblock ~27 ~1 ~8 minecraft:blackstone
setblock ~27 ~2 ~8 minecraft:blackstone
setblock ~27 ~3 ~8 minecraft:blackstone
setblock ~27 ~0 ~9 minecraft:blackstone
setblock ~27 ~0 ~10 minecraft:blackstone
setblock ~27 ~0 ~11 minecraft:blackstone
setblock ~27 ~0 ~12 minecraft:blackstone
setblock ~27 ~0 ~13 minecraft:blackstone
setblock ~27 ~0 ~14 minecraft:blackstone
setblock ~27 ~0 ~15 minecraft:blackstone
setblock ~27 ~0 ~16 minecraft:blackstone
setblock ~27 ~0 ~17 minecraft:blackstone
setblock ~27 ~0 ~18 minecraft:blackstone
setblock ~27 ~0 ~19 minecraft:blackstone
setblock ~27 ~0 ~20 minecraft:blackstone
setblock ~27 ~0 ~21 minecraft:blackstone
setblock ~27 ~0 ~22 minecraft:blackstone
setblock ~27 ~1 ~22 minecraft:blackstone
setblock ~27 ~2 ~22 minecraft:blackstone
setblock ~27 ~3 ~22 minecraft:blackstone
setblock ~27 ~0 ~23 minecraft:blackstone
setblock ~27 ~1 ~23 minecraft:blackstone
setblock ~27 ~2 ~23 minecraft:blackstone
setblock ~27 ~3 ~23 minecraft:blackstone
setblock ~27 ~0 ~24 minecraft:blackstone
setblock ~27 ~1 ~24 minecraft:blackstone
setblock ~27 ~2 ~24 minecraft:blackstone
setblock ~27 ~3 ~24 minecraft:blackstone
setblock ~28 ~0 ~7 minecraft:blackstone
setblock ~28 ~1 ~7 minecraft:blackstone
setblock ~28 ~2 ~7 minecraft:blackstone
setblock ~28 ~3 ~7 minecraft:blackstone
setblock ~28 ~0 ~8 minecraft:blackstone
setblock ~28 ~1 ~8 minecraft:blackstone
setblock ~28 ~2 ~8 minecraft:blackstone
setblock ~28 ~3 ~8 minecraft:blackstone
setblock ~28 ~0 ~9 minecraft:blackstone
setblock ~28 ~1 ~9 minecraft:blackstone
setblock ~28 ~2 ~9 minecraft:blackstone
setblock ~28 ~3 ~9 minecraft:blackstone
setblock ~28 ~0 ~10 minecraft:blackstone
setblock ~28 ~1 ~10 minecraft:blackstone
setblock ~28 ~2 ~10 minecraft:blackstone
setblock ~28 ~3 ~10 minecraft:blackstone
setblock ~28 ~0 ~11 minecraft:blackstone
setblock ~28 ~1 ~11 minecraft:blackstone
setblock ~28 ~2 ~11 minecraft:blackstone
setblock ~28 ~3 ~11 minecraft:blackstone
setblock ~28 ~0 ~12 minecraft:blackstone
setblock ~28 ~0 ~13 minecraft:blackstone
setblock ~28 ~0 ~14 minecraft:blackstone
setblock ~28 ~0 ~15 minecraft:blackstone
setblock ~28 ~0 ~16 minecraft:blackstone
setblock ~28 ~0 ~17 minecraft:blackstone
setblock ~28 ~0 ~18 minecraft:blackstone
setblock ~28 ~0 ~19 minecraft:blackstone
setblock ~28 ~1 ~19 minecraft:blackstone
setblock ~28 ~2 ~19 minecraft:blackstone
setblock ~28 ~3 ~19 minecraft:blackstone
setblock ~28 ~0 ~20 minecraft:blackstone
setblock ~28 ~1 ~20 minecraft:blackstone
setblock ~28 ~2 ~20 minecraft:blackstone
setblock ~28 ~3 ~20 minecraft:blackstone
setblock ~28 ~0 ~21 minecraft:blackstone
setblock ~28 ~1 ~21 minecraft:blackstone
setblock ~28 ~2 ~21 minecraft:blackstone
setblock ~28 ~3 ~21 minecraft:blackstone
setblock ~28 ~0 ~22 minecraft:blackstone
setblock ~28 ~1 ~22 minecraft:blackstone
setblock ~28 ~2 ~22 minecraft:blackstone
setblock ~28 ~3 ~22 minecraft:blackstone
setblock ~28 ~0 ~23 minecraft:blackstone
setblock ~28 ~1 ~23 minecraft:blackstone
setblock ~28 ~2 ~23 minecraft:blackstone
setblock ~28 ~3 ~23 minecraft:blackstone
setblock ~29 ~0 ~9 minecraft:blackstone
setblock ~29 ~1 ~9 minecraft:blackstone
setblock ~29 ~2 ~9 minecraft:blackstone
setblock ~29 ~3 ~9 minecraft:blackstone
setblock ~29 ~0 ~10 minecraft:blackstone
setblock ~29 ~1 ~10 minecraft:blackstone
setblock ~29 ~2 ~10 minecraft:blackstone
setblock ~29 ~3 ~10 minecraft:blackstone
setblock ~29 ~0 ~11 minecraft:blackstone
setblock ~29 ~1 ~11 minecraft:blackstone
setblock ~29 ~2 ~11 minecraft:blackstone
setblock ~29 ~3 ~11 minecraft:blackstone
setblock ~29 ~0 ~12 minecraft:blackstone
setblock ~29 ~1 ~12 minecraft:blackstone
setblock ~29 ~2 ~12 minecraft:blackstone
setblock ~29 ~3 ~12 minecraft:blackstone
setblock ~29 ~0 ~13 minecraft:blackstone
setblock ~29 ~1 ~13 minecraft:blackstone
setblock ~29 ~2 ~13 minecraft:blackstone
setblock ~29 ~3 ~13 minecraft:blackstone
setblock ~29 ~0 ~14 minecraft:blackstone
setblock ~29 ~1 ~14 minecraft:blackstone
setblock ~29 ~2 ~14 minecraft:blackstone
setblock ~29 ~3 ~14 minecraft:blackstone
setblock ~29 ~0 ~15 minecraft:blackstone
setblock ~29 ~1 ~15 minecraft:blackstone
setblock ~29 ~2 ~15 minecraft:blackstone
setblock ~29 ~3 ~15 minecraft:blackstone
setblock ~29 ~0 ~16 minecraft:blackstone
setblock ~29 ~1 ~16 minecraft:blackstone
setblock ~29 ~2 ~16 minecraft:blackstone
setblock ~29 ~3 ~16 minecraft:blackstone
setblock ~29 ~0 ~17 minecraft:blackstone
setblock ~29 ~1 ~17 minecraft:blackstone
setblock ~29 ~2 ~17 minecraft:blackstone
setblock ~29 ~3 ~17 minecraft:blackstone
setblock ~29 ~0 ~18 minecraft:blackstone
setblock ~29 ~1 ~18 minecraft:blackstone
setblock ~29 ~2 ~18 minecraft:blackstone
setblock ~29 ~3 ~18 minecraft:blackstone
setblock ~29 ~0 ~19 minecraft:blackstone
setblock ~29 ~1 ~19 minecraft:blackstone
setblock ~29 ~2 ~19 minecraft:blackstone
setblock ~29 ~3 ~19 minecraft:blackstone
setblock ~29 ~0 ~20 minecraft:blackstone
setblock ~29 ~1 ~20 minecraft:blackstone
setblock ~29 ~2 ~20 minecraft:blackstone
setblock ~29 ~3 ~20 minecraft:blackstone
setblock ~29 ~0 ~21 minecraft:blackstone
setblock ~29 ~1 ~21 minecraft:blackstone
setblock ~29 ~2 ~21 minecraft:blackstone
setblock ~29 ~3 ~21 minecraft:blackstone
setblock ~30 ~0 ~12 minecraft:blackstone
setblock ~30 ~1 ~12 minecraft:blackstone
setblock ~30 ~2 ~12 minecraft:blackstone
setblock ~30 ~3 ~12 minecraft:blackstone
setblock ~30 ~0 ~13 minecraft:blackstone
setblock ~30 ~1 ~13 minecraft:blackstone
setblock ~30 ~2 ~13 minecraft:blackstone
setblock ~30 ~3 ~13 minecraft:blackstone
setblock ~30 ~0 ~14 minecraft:blackstone
setblock ~30 ~1 ~14 minecraft:blackstone
setblock ~30 ~2 ~14 minecraft:blackstone
setblock ~30 ~3 ~14 minecraft:blackstone
setblock ~30 ~0 ~15 minecraft:blackstone
setblock ~30 ~1 ~15 minecraft:blackstone
setblock ~30 ~2 ~15 minecraft:blackstone
setblock ~30 ~3 ~15 minecraft:blackstone
setblock ~30 ~0 ~16 minecraft:blackstone
setblock ~30 ~1 ~16 minecraft:blackstone
setblock ~30 ~2 ~16 minecraft:blackstone
setblock ~30 ~3 ~16 minecraft:blackstone
setblock ~30 ~0 ~17 minecraft:blackstone
setblock ~30 ~1 ~17 minecraft:blackstone
setblock ~30 ~2 ~17 minecraft:blackstone
setblock ~30 ~3 ~17 minecraft:blackstone
setblock ~30 ~0 ~18 minecraft:blackstone
setblock ~30 ~1 ~18 minecraft:blackstone
setblock ~30 ~2 ~18 minecraft:blackstone
setblock ~30 ~3 ~18 minecraft:blackstone
setblock ~1 ~4 ~12 minecraft:smooth_quartz
setblock ~1 ~5 ~12 minecraft:smooth_quartz
setblock ~1 ~6 ~12 minecraft:smooth_quartz
setblock ~1 ~4 ~13 minecraft:smooth_quartz
setblock ~1 ~5 ~13 minecraft:smooth_quartz
setblock ~1 ~6 ~13 minecraft:smooth_quartz
setblock ~1 ~4 ~14 minecraft:smooth_quartz
setblock ~1 ~5 ~14 minecraft:smooth_quartz
setblock ~1 ~6 ~14 minecraft:smooth_quartz
setblock ~1 ~4 ~15 minecraft:smooth_quartz
setblock ~1 ~5 ~15 minecraft:smooth_quartz
setblock ~1 ~6 ~15 minecraft:smooth_quartz
setblock ~1 ~4 ~16 minecraft:smooth_quartz
setblock ~1 ~5 ~16 minecraft:smooth_quartz
setblock ~1 ~6 ~16 minecraft:smooth_quartz
setblock ~1 ~4 ~17 minecraft:smooth_quartz
setblock ~1 ~5 ~17 minecraft:smooth_quartz
setblock ~1 ~6 ~17 minecraft:smooth_quartz
setblock ~1 ~4 ~18 minecraft:smooth_quartz
setblock ~1 ~5 ~18 minecraft:smooth_quartz
setblock ~1 ~6 ~18 minecraft:smooth_quartz
setblock ~2 ~4 ~9 minecraft:smooth_quartz
setblock ~2 ~5 ~9 minecraft:smooth_quartz
setblock ~2 ~6 ~9 minecraft:smooth_quartz
setblock ~2 ~4 ~10 minecraft:smooth_quartz
setblock ~2 ~5 ~10 minecraft:smooth_quartz
setblock ~2 ~6 ~10 minecraft:smooth_quartz
setblock ~2 ~4 ~11 minecraft:smooth_quartz
setblock ~2 ~5 ~11 minecraft:smooth_quartz
setblock ~2 ~6 ~11 minecraft:smooth_quartz
setblock ~2 ~4 ~12 minecraft:smooth_quartz
setblock ~2 ~5 ~12 minecraft:smooth_quartz
setblock ~2 ~6 ~12 minecraft:smooth_quartz
setblock ~2 ~4 ~13 minecraft:smooth_quartz
setblock ~2 ~5 ~13 minecraft:smooth_quartz
setblock ~2 ~6 ~13 minecraft:smooth_quartz
setblock ~2 ~4 ~14 minecraft:smooth_quartz
setblock ~2 ~5 ~14 minecraft:smooth_quartz
setblock ~2 ~6 ~14 minecraft:smooth_quartz
setblock ~2 ~4 ~15 minecraft:smooth_quartz
setblock ~2 ~5 ~15 minecraft:smooth_quartz
setblock ~2 ~6 ~15 minecraft:smooth_quartz
setblock ~2 ~4 ~16 minecraft:smooth_quartz
setblock ~2 ~5 ~16 minecraft:smooth_quartz
setblock ~2 ~6 ~16 minecraft:smooth_quartz
setblock ~2 ~4 ~17 minecraft:smooth_quartz
setblock ~2 ~5 ~17 minecraft:smooth_quartz
setblock ~2 ~6 ~17 minecraft:smooth_quartz
setblock ~2 ~4 ~18 minecraft:smooth_quartz
setblock ~2 ~5 ~18 minecraft:smooth_quartz
setblock ~2 ~6 ~18 minecraft:smooth_quartz
setblock ~2 ~4 ~19 minecraft:smooth_quartz
setblock ~2 ~5 ~19 minecraft:smooth_quartz
setblock ~2 ~6 ~19 minecraft:smooth_quartz
setblock ~2 ~4 ~20 minecraft:smooth_quartz
setblock ~2 ~5 ~20 minecraft:smooth_quartz
setblock ~2 ~6 ~20 minecraft:smooth_quartz
setblock ~2 ~4 ~21 minecraft:smooth_quartz
setblock ~2 ~5 ~21 minecraft:smooth_quartz
setblock ~2 ~6 ~21 minecraft:smooth_quartz
setblock ~3 ~4 ~7 minecraft:smooth_quartz
setblock ~3 ~5 ~7 minecraft:smooth_quartz
setblock ~3 ~6 ~7 minecraft:smooth_quartz
setblock ~3 ~4 ~8 minecraft:smooth_quartz
setblock ~3 ~5 ~8 minecraft:smooth_quartz
setblock ~3 ~6 ~8 minecraft:smooth_quartz
setblock ~3 ~4 ~9 minecraft:smooth_quartz
setblock ~3 ~5 ~9 minecraft:smooth_quartz
setblock ~3 ~6 ~9 minecraft:smooth_quartz
setblock ~3 ~4 ~10 minecraft:smooth_quartz
setblock ~3 ~5 ~10 minecraft:smooth_quartz
setblock ~3 ~6 ~10 minecraft:smooth_quartz
setblock ~3 ~4 ~11 minecraft:smooth_quartz
setblock ~3 ~5 ~11 minecraft:smooth_quartz
setblock ~3 ~6 ~11 minecraft:smooth_quartz
setblock ~3 ~4 ~12 minecraft:smooth_quartz
setblock ~3 ~4 ~13 minecraft:smooth_quartz
setblock ~3 ~4 ~14 minecraft:smooth_quartz
setblock ~3 ~4 ~15 minecraft:smooth_quartz
setblock ~3 ~4 ~16 minecraft:smooth_quartz
setblock ~3 ~4 ~17 minecraft:smooth_quartz
setblock ~3 ~4 ~18 minecraft:smooth_quartz
setblock ~3 ~4 ~19 minecraft:smooth_quartz
setblock ~3 ~5 ~19 minecraft:smooth_quartz
setblock ~3 ~6 ~19 minecraft:smooth_quartz
setblock ~3 ~4 ~20 minecraft:smooth_quartz
setblock ~3 ~5 ~20 minecraft:smooth_quartz
setblock ~3 ~6 ~20 minecraft:smooth_quartz
setblock ~3 ~4 ~21 minecraft:smooth_quartz
setblock ~3 ~5 ~21 minecraft:smooth_quartz
setblock ~3 ~6 ~21 minecraft:smooth_quartz
setblock ~3 ~4 ~22 minecraft:smooth_quartz
setblock ~3 ~5 ~22 minecraft:smooth_quartz
setblock ~3 ~6 ~22 minecraft:smooth_quartz
setblock ~3 ~4 ~23 minecraft:smooth_quartz
setblock ~3 ~5 ~23 minecraft:smooth_quartz
setblock ~3 ~6 ~23 minecraft:smooth_quartz
setblock ~4 ~4 ~6 minecraft:smooth_quartz
setblock ~4 ~5 ~6 minecraft:smooth_quartz
setblock ~4 ~6 ~6 minecraft:smooth_quartz
setblock ~4 ~4 ~7 minecraft:smooth_quartz
setblock ~4 ~5 ~7 minecraft:smooth_quartz
setblock ~4 ~6 ~7 minecraft:smooth_quartz
setblock ~4 ~4 ~8 minecraft:smooth_quartz
setblock ~4 ~5 ~8 minecraft:smooth_quartz
setblock ~4 ~6 ~8 minecraft:smooth_quartz
setblock ~4 ~4 ~9 minecraft:smooth_quartz
setblock ~4 ~5 ~9 minecraft:smooth_quartz
setblock ~4 ~6 ~9 minecraft:smooth_quartz
setblock ~4 ~4 ~10 minecraft:smooth_quartz
setblock ~4 ~4 ~11 minecraft:smooth_quartz
setblock ~4 ~4 ~12 minecraft:smooth_quartz
setblock ~4 ~4 ~13 minecraft:smooth_quartz
setblock ~4 ~4 ~14 minecraft:smooth_quartz
setblock ~4 ~4 ~15 minecraft:smooth_quartz
setblock ~4 ~4 ~16 minecraft:smooth_quartz
setblock ~4 ~4 ~17 minecraft:smooth_quartz
setblock ~4 ~4 ~18 minecraft:smooth_quartz
setblock ~4 ~4 ~19 minecraft:smooth_quartz
setblock ~4 ~4 ~20 minecraft:smooth_quartz
setblock ~4 ~4 ~21 minecraft:smooth_quartz
setblock ~4 ~5 ~21 minecraft:smooth_quartz
setblock ~4 ~6 ~21 minecraft:smooth_quartz
setblock ~4 ~4 ~22 minecraft:smooth_quartz
setblock ~4 ~5 ~22 minecraft:smooth_quartz
setblock ~4 ~6 ~22 minecraft:smooth_quartz
setblock ~4 ~4 ~23 minecraft:smooth_quartz
setblock ~4 ~5 ~23 minecraft:smooth_quartz
setblock ~4 ~6 ~23 minecraft:smooth_quartz
setblock ~4 ~4 ~24 minecraft:smooth_quartz
setblock ~4 ~5 ~24 minecraft:smooth_quartz
setblock ~4 ~6 ~24 minecraft:smooth_quartz
setblock ~5 ~4 ~5 minecraft:smooth_quartz
setblock ~5 ~5 ~5 minecraft:smooth_quartz
setblock ~5 ~6 ~5 minecraft:smooth_quartz
setblock ~5 ~4 ~6 minecraft:smooth_quartz
setblock ~5 ~5 ~6 minecraft:smooth_quartz
setblock ~5 ~6 ~6 minecraft:smooth_quartz
setblock ~5 ~4 ~7 minecraft:smooth_quartz
setblock ~5 ~5 ~7 minecraft:smooth_quartz
setblock ~5 ~6 ~7 minecraft:smooth_quartz
setblock ~5 ~4 ~8 minecraft:smooth_quartz
setblock ~5 ~4 ~9 minecraft:smooth_quartz
setblock ~5 ~4 ~10 minecraft:smooth_quartz
setblock ~5 ~4 ~11 minecraft:smooth_quartz
setblock ~5 ~4 ~12 minecraft:smooth_quartz
setblock ~5 ~4 ~13 minecraft:smooth_quartz
setblock ~5 ~4 ~14 minecraft:smooth_quartz
setblock ~5 ~4 ~15 minecraft:smooth_quartz
setblock ~5 ~4 ~16 minecraft:smooth_quartz
setblock ~5 ~4 ~17 minecraft:smooth_quartz
setblock ~5 ~4 ~18 minecraft:smooth_quartz
setblock ~5 ~4 ~19 minecraft:smooth_quartz
setblock ~5 ~4 ~20 minecraft:smooth_quartz
setblock ~5 ~4 ~21 minecraft:smooth_quartz
setblock ~5 ~4 ~22 minecraft:smooth_quartz
setblock ~5 ~4 ~23 minecraft:smooth_quartz
setblock ~5 ~5 ~23 minecraft:smooth_quartz
setblock ~5 ~6 ~23 minecraft:smooth_quartz
setblock ~5 ~4 ~24 minecraft:smooth_quartz
setblock ~5 ~5 ~24 minecraft:smooth_quartz
setblock ~5 ~6 ~24 minecraft:smooth_quartz
setblock ~5 ~4 ~25 minecraft:smooth_quartz
setblock ~5 ~5 ~25 minecraft:smooth_quartz
setblock ~5 ~6 ~25 minecraft:smooth_quartz
setblock ~6 ~4 ~4 minecraft:smooth_quartz
setblock ~6 ~5 ~4 minecraft:smooth_quartz
setblock ~6 ~6 ~4 minecraft:smooth_quartz
setblock ~6 ~4 ~5 minecraft:smooth_quartz
setblock ~6 ~5 ~5 minecraft:smooth_quartz
setblock ~6 ~6 ~5 minecraft:smooth_quartz
setblock ~6 ~4 ~6 minecraft:smooth_quartz
setblock ~6 ~5 ~6 minecraft:smooth_quartz
setblock ~6 ~6 ~6 minecraft:smooth_quartz
setblock ~6 ~4 ~7 minecraft:smooth_quartz
setblock ~6 ~4 ~8 minecraft:smooth_quartz
setblock ~6 ~4 ~9 minecraft:smooth_quartz
setblock ~6 ~4 ~10 minecraft:smooth_quartz
setblock ~6 ~4 ~11 minecraft:smooth_quartz
setblock ~6 ~4 ~12 minecraft:smooth_quartz
setblock ~6 ~4 ~13 minecraft:smooth_quartz
setblock ~6 ~4 ~14 minecraft:smooth_quartz
setblock ~6 ~4 ~15 minecraft:smooth_quartz
setblock ~6 ~4 ~16 minecraft:smooth_quartz
setblock ~6 ~4 ~17 minecraft:smooth_quartz
setblock ~6 ~4 ~18 minecraft:smooth_quartz
setblock ~6 ~4 ~19 minecraft:smooth_quartz
setblock ~6 ~4 ~20 minecraft:smooth_quartz
setblock ~6 ~4 ~21 minecraft:smooth_quartz
setblock ~6 ~4 ~22 minecraft:smooth_quartz
setblock ~6 ~4 ~23 minecraft:smooth_quartz
setblock ~6 ~4 ~24 minecraft:smooth_quartz
setblock ~6 ~5 ~24 minecraft:smooth_quartz
setblock ~6 ~6 ~24 minecraft:smooth_quartz
setblock ~6 ~4 ~25 minecraft:smooth_quartz
setblock ~6 ~5 ~25 minecraft:smooth_quartz
setblock ~6 ~6 ~25 minecraft:smooth_quartz
setblock ~6 ~4 ~26 minecraft:smooth_quartz
setblock ~6 ~5 ~26 minecraft:smooth_quartz
setblock ~6 ~6 ~26 minecraft:smooth_quartz
setblock ~7 ~4 ~3 minecraft:smooth_quartz
setblock ~7 ~5 ~3 minecraft:smooth_quartz
setblock ~7 ~6 ~3 minecraft:smooth_quartz
setblock ~7 ~4 ~4 minecraft:smooth_quartz
setblock ~7 ~5 ~4 minecraft:smooth_quartz
setblock ~7 ~6 ~4 minecraft:smooth_quartz
setblock ~7 ~4 ~5 minecraft:smooth_quartz
setblock ~7 ~5 ~5 minecraft:smooth_quartz
setblock ~7 ~6 ~5 minecraft:smooth_quartz
setblock ~7 ~4 ~6 minecraft:smooth_quartz
setblock ~7 ~4 ~7 minecraft:smooth_quartz
setblock ~7 ~4 ~8 minecraft:smooth_quartz
setblock ~7 ~4 ~9 minecraft:smooth_quartz
setblock ~7 ~4 ~10 minecraft:smooth_quartz
setblock ~7 ~4 ~11 minecraft:smooth_quartz
setblock ~7 ~4 ~12 minecraft:smooth_quartz
setblock ~7 ~4 ~13 minecraft:smooth_quartz
setblock ~7 ~4 ~14 minecraft:smooth_quartz
setblock ~7 ~4 ~15 minecraft:smooth_quartz
setblock ~7 ~4 ~16 minecraft:smooth_quartz
setblock ~7 ~4 ~17 minecraft:smooth_quartz
setblock ~7 ~4 ~18 minecraft:smooth_quartz
setblock ~7 ~4 ~19 minecraft:smooth_quartz
setblock ~7 ~4 ~20 minecraft:smooth_quartz
setblock ~7 ~4 ~21 minecraft:smooth_quartz
setblock ~7 ~4 ~22 minecraft:smooth_quartz
setblock ~7 ~4 ~23 minecraft:smooth_quartz
setblock ~7 ~4 ~24 minecraft:smooth_quartz
setblock ~7 ~4 ~25 minecraft:smooth_quartz
setblock ~7 ~5 ~25 minecraft:smooth_quartz
setblock ~7 ~6 ~25 minecraft:smooth_quartz
setblock ~7 ~4 ~26 minecraft:smooth_quartz
setblock ~7 ~5 ~26 minecraft:smooth_quartz
setblock ~7 ~6 ~26 minecraft:smooth_quartz
setblock ~7 ~4 ~27 minecraft:smooth_quartz
setblock ~7 ~5 ~27 minecraft:smooth_quartz
setblock ~7 ~6 ~27 minecraft:smooth_quartz
setblock ~8 ~4 ~3 minecraft:smooth_quartz
setblock ~8 ~5 ~3 minecraft:smooth_quartz
setblock ~8 ~6 ~3 minecraft:smooth_quartz
setblock ~8 ~4 ~4 minecraft:smooth_quartz
setblock ~8 ~5 ~4 minecraft:smooth_quartz
setblock ~8 ~6 ~4 minecraft:smooth_quartz
setblock ~8 ~4 ~5 minecraft:smooth_quartz
setblock ~8 ~4 ~6 minecraft:smooth_quartz
setblock ~8 ~4 ~7 minecraft:smooth_quartz
setblock ~8 ~4 ~8 minecraft:smooth_quartz
setblock ~8 ~4 ~9 minecraft:smooth_quartz
setblock ~8 ~4 ~10 minecraft:smooth_quartz
setblock ~8 ~4 ~11 minecraft:smooth_quartz
setblock ~8 ~4 ~12 minecraft:smooth_quartz
setblock ~8 ~4 ~13 minecraft:smooth_quartz
setblock ~8 ~4 ~14 minecraft:smooth_quartz
setblock ~8 ~4 ~15 minecraft:smooth_quartz
setblock ~8 ~4 ~16 minecraft:smooth_quartz
setblock ~8 ~4 ~17 minecraft:smooth_quartz
setblock ~8 ~4 ~18 minecraft:smooth_quartz
setblock ~8 ~4 ~19 minecraft:smooth_quartz
setblock ~8 ~4 ~20 minecraft:smooth_quartz
setblock ~8 ~4 ~21 minecraft:smooth_quartz
setblock ~8 ~4 ~22 minecraft:smooth_quartz
setblock ~8 ~4 ~23 minecraft:smooth_quartz
setblock ~8 ~4 ~24 minecraft:smooth_quartz
setblock ~8 ~4 ~25 minecraft:smooth_quartz
setblock ~8 ~4 ~26 minecraft:smooth_quartz
setblock ~8 ~5 ~26 minecraft:smooth_quartz
setblock ~8 ~6 ~26 minecraft:smooth_quartz
setblock ~8 ~4 ~27 minecraft:smooth_quartz
setblock ~8 ~5 ~27 minecraft:smooth_quartz
setblock ~8 ~6 ~27 minecraft:smooth_quartz
setblock ~9 ~4 ~2 minecraft:smooth_quartz
setblock ~9 ~5 ~2 minecraft:smooth_quartz
setblock ~9 ~6 ~2 minecraft:smooth_quartz
setblock ~9 ~4 ~3 minecraft:smooth_quartz
setblock ~9 ~5 ~3 minecraft:smooth_quartz
setblock ~9 ~6 ~3 minecraft:smooth_quartz
setblock ~9 ~4 ~4 minecraft:smooth_quartz
setblock ~9 ~5 ~4 minecraft:smooth_quartz
setblock ~9 ~6 ~4 minecraft:smooth_quartz
setblock ~9 ~4 ~5 minecraft:smooth_quartz
setblock ~9 ~4 ~6 minecraft:smooth_quartz
setblock ~9 ~4 ~7 minecraft:smooth_quartz
setblock ~9 ~4 ~8 minecraft:smooth_quartz
setblock ~9 ~4 ~9 minecraft:smooth_quartz
setblock ~9 ~4 ~10 minecraft:smooth_quartz
setblock ~9 ~4 ~11 minecraft:smooth_quartz
setblock ~9 ~4 ~12 minecraft:smooth_quartz
setblock ~9 ~4 ~13 minecraft:smooth_quartz
setblock ~9 ~4 ~14 minecraft:smooth_quartz
setblock ~9 ~4 ~15 minecraft:smooth_quartz
setblock ~9 ~4 ~16 minecraft:smooth_quartz
setblock ~9 ~4 ~17 minecraft:smooth_quartz
setblock ~9 ~4 ~18 minecraft:smooth_quartz
setblock ~9 ~4 ~19 minecraft:smooth_quartz
setblock ~9 ~4 ~20 minecraft:smooth_quartz
setblock ~9 ~4 ~21 minecraft:smooth_quartz
setblock ~9 ~4 ~22 minecraft:smooth_quartz
setblock ~9 ~4 ~23 minecraft:smooth_quartz
setblock ~9 ~4 ~24 minecraft:smooth_quartz
setblock ~9 ~4 ~25 minecraft:smooth_quartz
setblock ~9 ~4 ~26 minecraft:smooth_quartz
setblock ~9 ~5 ~26 minecraft:smooth_quartz
setblock ~9 ~6 ~26 minecraft:smooth_quartz
setblock ~9 ~4 ~27 minecraft:smooth_quartz
setblock ~9 ~5 ~27 minecraft:smooth_quartz
setblock ~9 ~6 ~27 minecraft:smooth_quartz
setblock ~9 ~4 ~28 minecraft:smooth_quartz
setblock ~9 ~5 ~28 minecraft:smooth_quartz
setblock ~9 ~6 ~28 minecraft:smooth_quartz
setblock ~10 ~4 ~2 minecraft:smooth_quartz
setblock ~10 ~5 ~2 minecraft:smooth_quartz
setblock ~10 ~6 ~2 minecraft:smooth_quartz
setblock ~10 ~4 ~3 minecraft:smooth_quartz
setblock ~10 ~5 ~3 minecraft:smooth_quartz
setblock ~10 ~6 ~3 minecraft:smooth_quartz
setblock ~10 ~4 ~4 minecraft:smooth_quartz
setblock ~10 ~4 ~5 minecraft:smooth_quartz
setblock ~10 ~4 ~6 minecraft:smooth_quartz
setblock ~10 ~4 ~7 minecraft:smooth_quartz
setblock ~10 ~4 ~8 minecraft:smooth_quartz
setblock ~10 ~4 ~9 minecraft:smooth_quartz
setblock ~10 ~4 ~10 minecraft:smooth_quartz
setblock ~10 ~4 ~11 minecraft:smooth_quartz
setblock ~10 ~4 ~12 minecraft:smooth_quartz
setblock ~10 ~4 ~13 minecraft:smooth_quartz
setblock ~10 ~4 ~14 minecraft:smooth_quartz
setblock ~10 ~4 ~15 minecraft:smooth_quartz
setblock ~10 ~4 ~16 minecraft:smooth_quartz
setblock ~10 ~4 ~17 minecraft:smooth_quartz
setblock ~10 ~4 ~18 minecraft:smooth_quartz
setblock ~10 ~4 ~19 minecraft:smooth_quartz
setblock ~10 ~4 ~20 minecraft:smooth_quartz
setblock ~10 ~4 ~21 minecraft:smooth_quartz
setblock ~10 ~4 ~22 minecraft:smooth_quartz
setblock ~10 ~4 ~23 minecraft:smooth_quartz
setblock ~10 ~4 ~24 minecraft:smooth_quartz
setblock ~10 ~4 ~25 minecraft:smooth_quartz
setblock ~10 ~4 ~26 minecraft:smooth_quartz
setblock ~10 ~4 ~27 minecraft:smooth_quartz
setblock ~10 ~5 ~27 minecraft:smooth_quartz
setblock ~10 ~6 ~27 minecraft:smooth_quartz
setblock ~10 ~4 ~28 minecraft:smooth_quartz
setblock ~10 ~5 ~28 minecraft:smooth_quartz
setblock ~10 ~6 ~28 minecraft:smooth_quartz
setblock ~11 ~4 ~2 minecraft:smooth_quartz
setblock ~11 ~5 ~2 minecraft:smooth_quartz
setblock ~11 ~6 ~2 minecraft:smooth_quartz
setblock ~11 ~4 ~3 minecraft:smooth_quartz
setblock ~11 ~5 ~3 minecraft:smooth_quartz
setblock ~11 ~6 ~3 minecraft:smooth_quartz
setblock ~11 ~4 ~4 minecraft:smooth_quartz
setblock ~11 ~4 ~5 minecraft:smooth_quartz
setblock ~11 ~4 ~6 minecraft:smooth_quartz
setblock ~11 ~4 ~7 minecraft:smooth_quartz
setblock ~11 ~4 ~8 minecraft:smooth_quartz
setblock ~11 ~4 ~9 minecraft:smooth_quartz
setblock ~11 ~4 ~10 minecraft:smooth_quartz
setblock ~11 ~4 ~11 minecraft:smooth_quartz
setblock ~11 ~4 ~12 minecraft:smooth_quartz
setblock ~11 ~4 ~13 minecraft:smooth_quartz
setblock ~11 ~4 ~14 minecraft:smooth_quartz
setblock ~11 ~4 ~15 minecraft:smooth_quartz
setblock ~11 ~4 ~16 minecraft:smooth_quartz
setblock ~11 ~4 ~17 minecraft:smooth_quartz
setblock ~11 ~4 ~18 minecraft:smooth_quartz
setblock ~11 ~4 ~19 minecraft:smooth_quartz
setblock ~11 ~4 ~20 minecraft:smooth_quartz
setblock ~11 ~4 ~21 minecraft:smooth_quartz
setblock ~11 ~4 ~22 minecraft:smooth_quartz
setblock ~11 ~4 ~23 minecraft:smooth_quartz
setblock ~11 ~4 ~24 minecraft:smooth_quartz
setblock ~11 ~4 ~25 minecraft:smooth_quartz
setblock ~11 ~4 ~26 minecraft:smooth_quartz
setblock ~11 ~4 ~27 minecraft:smooth_quartz
setblock ~11 ~5 ~27 minecraft:smooth_quartz
setblock ~11 ~6 ~27 minecraft:smooth_quartz
setblock ~11 ~4 ~28 minecraft:smooth_quartz
setblock ~11 ~5 ~28 minecraft:smooth_quartz
setblock ~11 ~6 ~28 minecraft:smooth_quartz
setblock ~12 ~4 ~1 minecraft:smooth_quartz
setblock ~12 ~5 ~1 minecraft:smooth_quartz
setblock ~12 ~6 ~1 minecraft:smooth_quartz
setblock ~12 ~4 ~2 minecraft:smooth_quartz
setblock ~12 ~5 ~2 minecraft:smooth_quartz
setblock ~12 ~6 ~2 minecraft:smooth_quartz
setblock ~12 ~4 ~3 minecraft:smooth_quartz
setblock ~12 ~4 ~4 minecraft:smooth_quartz
setblock ~12 ~4 ~5 minecraft:smooth_quartz
setblock ~12 ~4 ~6 minecraft:smooth_quartz
setblock ~12 ~4 ~7 minecraft:smooth_quartz
setblock ~12 ~4 ~8 minecraft:smooth_quartz
setblock ~12 ~4 ~9 minecraft:smooth_quartz
setblock ~12 ~4 ~10 minecraft:smooth_quartz
setblock ~12 ~4 ~11 minecraft:smooth_quartz
setblock ~12 ~4 ~12 minecraft:smooth_quartz
setblock ~12 ~4 ~13 minecraft:smooth_quartz
setblock ~12 ~4 ~14 minecraft:smooth_quartz
setblock ~12 ~4 ~15 minecraft:smooth_quartz
setblock ~12 ~4 ~16 minecraft:smooth_quartz
setblock ~12 ~4 ~17 minecraft:smooth_quartz
setblock ~12 ~4 ~18 minecraft:smooth_quartz
setblock ~12 ~4 ~19 minecraft:smooth_quartz
setblock ~12 ~4 ~20 minecraft:smooth_quartz
setblock ~12 ~4 ~21 minecraft:smooth_quartz
setblock ~12 ~4 ~22 minecraft:smooth_quartz
setblock ~12 ~4 ~23 minecraft:smooth_quartz
setblock ~12 ~4 ~24 minecraft:smooth_quartz
setblock ~12 ~4 ~25 minecraft:smooth_quartz
setblock ~12 ~4 ~26 minecraft:smooth_quartz
setblock ~12 ~4 ~27 minecraft:smooth_quartz
setblock ~12 ~4 ~28 minecraft:smooth_quartz
setblock ~12 ~5 ~28 minecraft:smooth_quartz
setblock ~12 ~6 ~28 minecraft:smooth_quartz
setblock ~12 ~4 ~29 minecraft:smooth_quartz
setblock ~12 ~5 ~29 minecraft:smooth_quartz
setblock ~12 ~6 ~29 minecraft:smooth_quartz
setblock ~13 ~4 ~1 minecraft:smooth_quartz
setblock ~13 ~5 ~1 minecraft:smooth_quartz
setblock ~13 ~6 ~1 minecraft:smooth_quartz
setblock ~13 ~4 ~2 minecraft:smooth_quartz
setblock ~13 ~5 ~2 minecraft:smooth_quartz
setblock ~13 ~6 ~2 minecraft:smooth_quartz
setblock ~13 ~4 ~3 minecraft:smooth_quartz
setblock ~13 ~4 ~4 minecraft:smooth_quartz
setblock ~13 ~4 ~5 minecraft:smooth_quartz
setblock ~13 ~4 ~6 minecraft:smooth_quartz
setblock ~13 ~4 ~7 minecraft:smooth_quartz
setblock ~13 ~4 ~8 minecraft:smooth_quartz
setblock ~13 ~4 ~9 minecraft:smooth_quartz
setblock ~13 ~4 ~10 minecraft:smooth_quartz
setblock ~13 ~4 ~11 minecraft:smooth_quartz
setblock ~13 ~4 ~12 minecraft:smooth_quartz
setblock ~13 ~4 ~13 minecraft:smooth_quartz
setblock ~13 ~4 ~14 minecraft:smooth_quartz
setblock ~13 ~4 ~15 minecraft:smooth_quartz
setblock ~13 ~4 ~16 minecraft:smooth_quartz
setblock ~13 ~4 ~17 minecraft:smooth_quartz
setblock ~13 ~4 ~18 minecraft:smooth_quartz
setblock ~13 ~4 ~19 minecraft:smooth_quartz
setblock ~13 ~4 ~20 minecraft:smooth_quartz
setblock ~13 ~4 ~21 minecraft:smooth_quartz
setblock ~13 ~4 ~22 minecraft:smooth_quartz
setblock ~13 ~4 ~23 minecraft:smooth_quartz
setblock ~13 ~4 ~24 minecraft:smooth_quartz
setblock ~13 ~4 ~25 minecraft:smooth_quartz
setblock ~13 ~4 ~26 minecraft:smooth_quartz
setblock ~13 ~4 ~27 minecraft:smooth_quartz
setblock ~13 ~4 ~28 minecraft:smooth_quartz
setblock ~13 ~5 ~28 minecraft:smooth_quartz
setblock ~13 ~6 ~28 minecraft:smooth_quartz
setblock ~13 ~4 ~29 minecraft:smooth_quartz
setblock ~13 ~5 ~29 minecraft:smooth_quartz
setblock ~13 ~6 ~29 minecraft:smooth_quartz
setblock ~14 ~4 ~1 minecraft:smooth_quartz
setblock ~14 ~5 ~1 minecraft:smooth_quartz
setblock ~14 ~6 ~1 minecraft:smooth_quartz
setblock ~14 ~4 ~2 minecraft:smooth_quartz
setblock ~14 ~5 ~2 minecraft:smooth_quartz
setblock ~14 ~6 ~2 minecraft:smooth_quartz
setblock ~14 ~4 ~3 minecraft:smooth_quartz
setblock ~14 ~4 ~4 minecraft:smooth_quartz
setblock ~14 ~4 ~5 minecraft:smooth_quartz
setblock ~14 ~4 ~6 minecraft:smooth_quartz
setblock ~14 ~4 ~7 minecraft:smooth_quartz
setblock ~14 ~4 ~8 minecraft:smooth_quartz
setblock ~14 ~4 ~9 minecraft:smooth_quartz
setblock ~14 ~4 ~10 minecraft:smooth_quartz
setblock ~14 ~4 ~11 minecraft:smooth_quartz
setblock ~14 ~4 ~12 minecraft:smooth_quartz
setblock ~14 ~4 ~13 minecraft:smooth_quartz
setblock ~14 ~4 ~14 minecraft:smooth_quartz
setblock ~14 ~4 ~15 minecraft:smooth_quartz
setblock ~14 ~4 ~16 minecraft:smooth_quartz
setblock ~14 ~4 ~17 minecraft:smooth_quartz
setblock ~14 ~4 ~18 minecraft:smooth_quartz
setblock ~14 ~4 ~19 minecraft:smooth_quartz
setblock ~14 ~4 ~20 minecraft:smooth_quartz
setblock ~14 ~4 ~21 minecraft:smooth_quartz
setblock ~14 ~4 ~22 minecraft:smooth_quartz
setblock ~14 ~4 ~23 minecraft:smooth_quartz
setblock ~14 ~4 ~24 minecraft:smooth_quartz
setblock ~14 ~4 ~25 minecraft:smooth_quartz
setblock ~14 ~4 ~26 minecraft:smooth_quartz
setblock ~14 ~4 ~27 minecraft:smooth_quartz
setblock ~14 ~4 ~28 minecraft:smooth_quartz
setblock ~14 ~5 ~28 minecraft:smooth_quartz
setblock ~14 ~6 ~28 minecraft:smooth_quartz
setblock ~14 ~4 ~29 minecraft:smooth_quartz
setblock ~14 ~5 ~29 minecraft:smooth_quartz
setblock ~14 ~6 ~29 minecraft:smooth_quartz
setblock ~15 ~4 ~1 minecraft:smooth_quartz
setblock ~15 ~5 ~1 minecraft:smooth_quartz
setblock ~15 ~6 ~1 minecraft:smooth_quartz
setblock ~15 ~4 ~2 minecraft:smooth_quartz
setblock ~15 ~5 ~2 minecraft:smooth_quartz
setblock ~15 ~6 ~2 minecraft:smooth_quartz
setblock ~15 ~4 ~3 minecraft:smooth_quartz
setblock ~15 ~4 ~4 minecraft:smooth_quartz
setblock ~15 ~4 ~5 minecraft:smooth_quartz
setblock ~15 ~4 ~6 minecraft:smooth_quartz
setblock ~15 ~4 ~7 minecraft:smooth_quartz
setblock ~15 ~4 ~8 minecraft:smooth_quartz
setblock ~15 ~4 ~9 minecraft:smooth_quartz
setblock ~15 ~4 ~10 minecraft:smooth_quartz
setblock ~15 ~4 ~11 minecraft:smooth_quartz
setblock ~15 ~4 ~12 minecraft:smooth_quartz
setblock ~15 ~4 ~13 minecraft:smooth_quartz
setblock ~15 ~4 ~14 minecraft:smooth_quartz
setblock ~15 ~4 ~15 minecraft:smooth_quartz
setblock ~15 ~4 ~16 minecraft:smooth_quartz
setblock ~15 ~4 ~17 minecraft:smooth_quartz
setblock ~15 ~4 ~18 minecraft:smooth_quartz
setblock ~15 ~4 ~19 minecraft:smooth_quartz
setblock ~15 ~4 ~20 minecraft:smooth_quartz
setblock ~15 ~4 ~21 minecraft:smooth_quartz
setblock ~15 ~4 ~22 minecraft:smooth_quartz
setblock ~15 ~4 ~23 minecraft:smooth_quartz
setblock ~15 ~4 ~24 minecraft:smooth_quartz
setblock ~15 ~4 ~25 minecraft:smooth_quartz
setblock ~15 ~4 ~26 minecraft:smooth_quartz
setblock ~15 ~4 ~27 minecraft:smooth_quartz
setblock ~15 ~4 ~28 minecraft:smooth_quartz
setblock ~15 ~5 ~28 minecraft:smooth_quartz
setblock ~15 ~6 ~28 minecraft:smooth_quartz
setblock ~15 ~4 ~29 minecraft:smooth_quartz
setblock ~15 ~5 ~29 minecraft:smooth_quartz
setblock ~15 ~6 ~29 minecraft:smooth_quartz
setblock ~16 ~4 ~1 minecraft:smooth_quartz
setblock ~16 ~5 ~1 minecraft:smooth_quartz
setblock ~16 ~6 ~1 minecraft:smooth_quartz
setblock ~16 ~4 ~2 minecraft:smooth_quartz
setblock ~16 ~5 ~2 minecraft:smooth_quartz
setblock ~16 ~6 ~2 minecraft:smooth_quartz
setblock ~16 ~4 ~3 minecraft:smooth_quartz
setblock ~16 ~4 ~4 minecraft:smooth_quartz
setblock ~16 ~4 ~5 minecraft:smooth_quartz
setblock ~16 ~4 ~6 minecraft:smooth_quartz
setblock ~16 ~4 ~7 minecraft:smooth_quartz
setblock ~16 ~4 ~8 minecraft:smooth_quartz
setblock ~16 ~4 ~9 minecraft:smooth_quartz
setblock ~16 ~4 ~10 minecraft:smooth_quartz
setblock ~16 ~4 ~11 minecraft:smooth_quartz
setblock ~16 ~4 ~12 minecraft:smooth_quartz
setblock ~16 ~4 ~13 minecraft:smooth_quartz
setblock ~16 ~4 ~14 minecraft:smooth_quartz
setblock ~16 ~4 ~15 minecraft:smooth_quartz
setblock ~16 ~4 ~16 minecraft:smooth_quartz
setblock ~16 ~4 ~17 minecraft:smooth_quartz
setblock ~16 ~4 ~18 minecraft:smooth_quartz
setblock ~16 ~4 ~19 minecraft:smooth_quartz
setblock ~16 ~4 ~20 minecraft:smooth_quartz
setblock ~16 ~4 ~21 minecraft:smooth_quartz
setblock ~16 ~4 ~22 minecraft:smooth_quartz
setblock ~16 ~4 ~23 minecraft:smooth_quartz
setblock ~16 ~4 ~24 minecraft:smooth_quartz
setblock ~16 ~4 ~25 minecraft:smooth_quartz
setblock ~16 ~4 ~26 minecraft:smooth_quartz
setblock ~16 ~4 ~27 minecraft:smooth_quartz
setblock ~16 ~4 ~28 minecraft:smooth_quartz
setblock ~16 ~5 ~28 minecraft:smooth_quartz
setblock ~16 ~6 ~28 minecraft:smooth_quartz
setblock ~16 ~4 ~29 minecraft:smooth_quartz
setblock ~16 ~5 ~29 minecraft:smooth_quartz
setblock ~16 ~6 ~29 minecraft:smooth_quartz
setblock ~17 ~4 ~1 minecraft:smooth_quartz
setblock ~17 ~5 ~1 minecraft:smooth_quartz
setblock ~17 ~6 ~1 minecraft:smooth_quartz
setblock ~17 ~4 ~2 minecraft:smooth_quartz
setblock ~17 ~5 ~2 minecraft:smooth_quartz
setblock ~17 ~6 ~2 minecraft:smooth_quartz
setblock ~17 ~4 ~3 minecraft:smooth_quartz
setblock ~17 ~4 ~4 minecraft:smooth_quartz
setblock ~17 ~4 ~5 minecraft:smooth_quartz
setblock ~17 ~4 ~6 minecraft:smooth_quartz
setblock ~17 ~4 ~7 minecraft:smooth_quartz
setblock ~17 ~4 ~8 minecraft:smooth_quartz
setblock ~17 ~4 ~9 minecraft:smooth_quartz
setblock ~17 ~4 ~10 minecraft:smooth_quartz
setblock ~17 ~4 ~11 minecraft:smooth_quartz
setblock ~17 ~4 ~12 minecraft:smooth_quartz
setblock ~17 ~4 ~13 minecraft:smooth_quartz
setblock ~17 ~4 ~14 minecraft:smooth_quartz
setblock ~17 ~4 ~15 minecraft:smooth_quartz
setblock ~17 ~4 ~16 minecraft:smooth_quartz
setblock ~17 ~4 ~17 minecraft:smooth_quartz
setblock ~17 ~4 ~18 minecraft:smooth_quartz
setblock ~17 ~4 ~19 minecraft:smooth_quartz
setblock ~17 ~4 ~20 minecraft:smooth_quartz
setblock ~17 ~4 ~21 minecraft:smooth_quartz
setblock ~17 ~4 ~22 minecraft:smooth_quartz
setblock ~17 ~4 ~23 minecraft:smooth_quartz
setblock ~17 ~4 ~24 minecraft:smooth_quartz
setblock ~17 ~4 ~25 minecraft:smooth_quartz
setblock ~17 ~4 ~26 minecraft:smooth_quartz
setblock ~17 ~4 ~27 minecraft:smooth_quartz
setblock ~17 ~4 ~28 minecraft:smooth_quartz
setblock ~17 ~5 ~28 minecraft:smooth_quartz
setblock ~17 ~6 ~28 minecraft:smooth_quartz
setblock ~17 ~4 ~29 minecraft:smooth_quartz
setblock ~17 ~5 ~29 minecraft:smooth_quartz
setblock ~17 ~6 ~29 minecraft:smooth_quartz
setblock ~18 ~4 ~1 minecraft:smooth_quartz
setblock ~18 ~5 ~1 minecraft:smooth_quartz
setblock ~18 ~6 ~1 minecraft:smooth_quartz
setblock ~18 ~4 ~2 minecraft:smooth_quartz
setblock ~18 ~5 ~2 minecraft:smooth_quartz
setblock ~18 ~6 ~2 minecraft:smooth_quartz
setblock ~18 ~4 ~3 minecraft:smooth_quartz
setblock ~18 ~4 ~4 minecraft:smooth_quartz
setblock ~18 ~4 ~5 minecraft:smooth_quartz
setblock ~18 ~4 ~6 minecraft:smooth_quartz
setblock ~18 ~4 ~7 minecraft:smooth_quartz
setblock ~18 ~4 ~8 minecraft:smooth_quartz
setblock ~18 ~4 ~9 minecraft:smooth_quartz
setblock ~18 ~4 ~10 minecraft:smooth_quartz
setblock ~18 ~4 ~11 minecraft:smooth_quartz
setblock ~18 ~4 ~12 minecraft:smooth_quartz
setblock ~18 ~4 ~13 minecraft:smooth_quartz
setblock ~18 ~4 ~14 minecraft:smooth_quartz
setblock ~18 ~4 ~15 minecraft:smooth_quartz
setblock ~18 ~4 ~16 minecraft:smooth_quartz
setblock ~18 ~4 ~17 minecraft:smooth_quartz
setblock ~18 ~4 ~18 minecraft:smooth_quartz
setblock ~18 ~4 ~19 minecraft:smooth_quartz
setblock ~18 ~4 ~20 minecraft:smooth_quartz
setblock ~18 ~4 ~21 minecraft:smooth_quartz
setblock ~18 ~4 ~22 minecraft:smooth_quartz
setblock ~18 ~4 ~23 minecraft:smooth_quartz
setblock ~18 ~4 ~24 minecraft:smooth_quartz
setblock ~18 ~4 ~25 minecraft:smooth_quartz
setblock ~18 ~4 ~26 minecraft:smooth_quartz
setblock ~18 ~4 ~27 minecraft:smooth_quartz
setblock ~18 ~4 ~28 minecraft:smooth_quartz
setblock ~18 ~5 ~28 minecraft:smooth_quartz
setblock ~18 ~6 ~28 minecraft:smooth_quartz
setblock ~18 ~4 ~29 minecraft:smooth_quartz
setblock ~18 ~5 ~29 minecraft:smooth_quartz
setblock ~18 ~6 ~29 minecraft:smooth_quartz
setblock ~19 ~4 ~2 minecraft:smooth_quartz
setblock ~19 ~5 ~2 minecraft:smooth_quartz
setblock ~19 ~6 ~2 minecraft:smooth_quartz
setblock ~19 ~4 ~3 minecraft:smooth_quartz
setblock ~19 ~5 ~3 minecraft:smooth_quartz
setblock ~19 ~6 ~3 minecraft:smooth_quartz
setblock ~19 ~4 ~4 minecraft:smooth_quartz
setblock ~19 ~4 ~5 minecraft:smooth_quartz
setblock ~19 ~4 ~6 minecraft:smooth_quartz
setblock ~19 ~4 ~7 minecraft:smooth_quartz
setblock ~19 ~4 ~8 minecraft:smooth_quartz
setblock ~19 ~4 ~9 minecraft:smooth_quartz
setblock ~19 ~4 ~10 minecraft:smooth_quartz
setblock ~19 ~4 ~11 minecraft:smooth_quartz
setblock ~19 ~4 ~12 minecraft:smooth_quartz
setblock ~19 ~4 ~13 minecraft:smooth_quartz
setblock ~19 ~4 ~14 minecraft:smooth_quartz
setblock ~19 ~4 ~15 minecraft:smooth_quartz
setblock ~19 ~4 ~16 minecraft:smooth_quartz
setblock ~19 ~4 ~17 minecraft:smooth_quartz
setblock ~19 ~4 ~18 minecraft:smooth_quartz
setblock ~19 ~4 ~19 minecraft:smooth_quartz
setblock ~19 ~4 ~20 minecraft:smooth_quartz
setblock ~19 ~4 ~21 minecraft:smooth_quartz
setblock ~19 ~4 ~22 minecraft:smooth_quartz
setblock ~19 ~4 ~23 minecraft:smooth_quartz
setblock ~19 ~4 ~24 minecraft:smooth_quartz
setblock ~19 ~4 ~25 minecraft:smooth_quartz
setblock ~19 ~4 ~26 minecraft:smooth_quartz
setblock ~19 ~4 ~27 minecraft:smooth_quartz
setblock ~19 ~5 ~27 minecraft:smooth_quartz
setblock ~19 ~6 ~27 minecraft:smooth_quartz
setblock ~19 ~4 ~28 minecraft:smooth_quartz
setblock ~19 ~5 ~28 minecraft:smooth_quartz
setblock ~19 ~6 ~28 minecraft:smooth_quartz
setblock ~20 ~4 ~2 minecraft:smooth_quartz
setblock ~20 ~5 ~2 minecraft:smooth_quartz
setblock ~20 ~6 ~2 minecraft:smooth_quartz
setblock ~20 ~4 ~3 minecraft:smooth_quartz
setblock ~20 ~5 ~3 minecraft:smooth_quartz
setblock ~20 ~6 ~3 minecraft:smooth_quartz
setblock ~20 ~4 ~4 minecraft:smooth_quartz
setblock ~20 ~4 ~5 minecraft:smooth_quartz
setblock ~20 ~4 ~6 minecraft:smooth_quartz
setblock ~20 ~4 ~7 minecraft:smooth_quartz
setblock ~20 ~4 ~8 minecraft:smooth_quartz
setblock ~20 ~4 ~9 minecraft:smooth_quartz
setblock ~20 ~4 ~10 minecraft:smooth_quartz
setblock ~20 ~4 ~11 minecraft:smooth_quartz
setblock ~20 ~4 ~12 minecraft:smooth_quartz
setblock ~20 ~4 ~13 minecraft:smooth_quartz
setblock ~20 ~4 ~14 minecraft:smooth_quartz
setblock ~20 ~4 ~15 minecraft:smooth_quartz
setblock ~20 ~4 ~16 minecraft:smooth_quartz
setblock ~20 ~4 ~17 minecraft:smooth_quartz
setblock ~20 ~4 ~18 minecraft:smooth_quartz
setblock ~20 ~4 ~19 minecraft:smooth_quartz
setblock ~20 ~4 ~20 minecraft:smooth_quartz
setblock ~20 ~4 ~21 minecraft:smooth_quartz
setblock ~20 ~4 ~22 minecraft:smooth_quartz
setblock ~20 ~4 ~23 minecraft:smooth_quartz
setblock ~20 ~4 ~24 minecraft:smooth_quartz
setblock ~20 ~4 ~25 minecraft:smooth_quartz
setblock ~20 ~4 ~26 minecraft:smooth_quartz
setblock ~20 ~4 ~27 minecraft:smooth_quartz
setblock ~20 ~5 ~27 minecraft:smooth_quartz
setblock ~20 ~6 ~27 minecraft:smooth_quartz
setblock ~20 ~4 ~28 minecraft:smooth_quartz
setblock ~20 ~5 ~28 minecraft:smooth_quartz
setblock ~20 ~6 ~28 minecraft:smooth_quartz
setblock ~21 ~4 ~2 minecraft:smooth_quartz
setblock ~21 ~5 ~2 minecraft:smooth_quartz
setblock ~21 ~6 ~2 minecraft:smooth_quartz
setblock ~21 ~4 ~3 minecraft:smooth_quartz
setblock ~21 ~5 ~3 minecraft:smooth_quartz
setblock ~21 ~6 ~3 minecraft:smooth_quartz
setblock ~21 ~4 ~4 minecraft:smooth_quartz
setblock ~21 ~5 ~4 minecraft:smooth_quartz
setblock ~21 ~6 ~4 minecraft:smooth_quartz
setblock ~21 ~4 ~5 minecraft:smooth_quartz
setblock ~21 ~4 ~6 minecraft:smooth_quartz
setblock ~21 ~4 ~7 minecraft:smooth_quartz
setblock ~21 ~4 ~8 minecraft:smooth_quartz
setblock ~21 ~4 ~9 minecraft:smooth_quartz
setblock ~21 ~4 ~10 minecraft:smooth_quartz
setblock ~21 ~4 ~11 minecraft:smooth_quartz
setblock ~21 ~4 ~12 minecraft:smooth_quartz
setblock ~21 ~4 ~13 minecraft:smooth_quartz
setblock ~21 ~4 ~14 minecraft:smooth_quartz
setblock ~21 ~4 ~15 minecraft:smooth_quartz
setblock ~21 ~4 ~16 minecraft:smooth_quartz
setblock ~21 ~4 ~17 minecraft:smooth_quartz
setblock ~21 ~4 ~18 minecraft:smooth_quartz
setblock ~21 ~4 ~19 minecraft:smooth_quartz
setblock ~21 ~4 ~20 minecraft:smooth_quartz
setblock ~21 ~4 ~21 minecraft:smooth_quartz
setblock ~21 ~4 ~22 minecraft:smooth_quartz
setblock ~21 ~4 ~23 minecraft:smooth_quartz
setblock ~21 ~4 ~24 minecraft:smooth_quartz
setblock ~21 ~4 ~25 minecraft:smooth_quartz
setblock ~21 ~4 ~26 minecraft:smooth_quartz
setblock ~21 ~5 ~26 minecraft:smooth_quartz
setblock ~21 ~6 ~26 minecraft:smooth_quartz
setblock ~21 ~4 ~27 minecraft:smooth_quartz
setblock ~21 ~5 ~27 minecraft:smooth_quartz
setblock ~21 ~6 ~27 minecraft:smooth_quartz
setblock ~21 ~4 ~28 minecraft:smooth_quartz
setblock ~21 ~5 ~28 minecraft:smooth_quartz
setblock ~21 ~6 ~28 minecraft:smooth_quartz
setblock ~22 ~4 ~3 minecraft:smooth_quartz
setblock ~22 ~5 ~3 minecraft:smooth_quartz
setblock ~22 ~6 ~3 minecraft:smooth_quartz
setblock ~22 ~4 ~4 minecraft:smooth_quartz
setblock ~22 ~5 ~4 minecraft:smooth_quartz
setblock ~22 ~6 ~4 minecraft:smooth_quartz
setblock ~22 ~4 ~5 minecraft:smooth_quartz
setblock ~22 ~4 ~6 minecraft:smooth_quartz
setblock ~22 ~4 ~7 minecraft:smooth_quartz
setblock ~22 ~4 ~8 minecraft:smooth_quartz
setblock ~22 ~4 ~9 minecraft:smooth_quartz
setblock ~22 ~4 ~10 minecraft:smooth_quartz
setblock ~22 ~4 ~11 minecraft:smooth_quartz
setblock ~22 ~4 ~12 minecraft:smooth_quartz
setblock ~22 ~4 ~13 minecraft:smooth_quartz
setblock ~22 ~4 ~14 minecraft:smooth_quartz
setblock ~22 ~4 ~15 minecraft:smooth_quartz
setblock ~22 ~4 ~16 minecraft:smooth_quartz
setblock ~22 ~4 ~17 minecraft:smooth_quartz
setblock ~22 ~4 ~18 minecraft:smooth_quartz
setblock ~22 ~4 ~19 minecraft:smooth_quartz
setblock ~22 ~4 ~20 minecraft:smooth_quartz
setblock ~22 ~4 ~21 minecraft:smooth_quartz
setblock ~22 ~4 ~22 minecraft:smooth_quartz
setblock ~22 ~4 ~23 minecraft:smooth_quartz
setblock ~22 ~4 ~24 minecraft:smooth_quartz
setblock ~22 ~4 ~25 minecraft:smooth_quartz
setblock ~22 ~4 ~26 minecraft:smooth_quartz
setblock ~22 ~5 ~26 minecraft:smooth_quartz
setblock ~22 ~6 ~26 minecraft:smooth_quartz
setblock ~22 ~4 ~27 minecraft:smooth_quartz
setblock ~22 ~5 ~27 minecraft:smooth_quartz
setblock ~22 ~6 ~27 minecraft:smooth_quartz
setblock ~23 ~4 ~3 minecraft:smooth_quartz
setblock ~23 ~5 ~3 minecraft:smooth_quartz
setblock ~23 ~6 ~3 minecraft:smooth_quartz
setblock ~23 ~4 ~4 minecraft:smooth_quartz
setblock ~23 ~5 ~4 minecraft:smooth_quartz
setblock ~23 ~6 ~4 minecraft:smooth_quartz
setblock ~23 ~4 ~5 minecraft:smooth_quartz
setblock ~23 ~5 ~5 minecraft:smooth_quartz
setblock ~23 ~6 ~5 minecraft:smooth_quartz
setblock ~23 ~4 ~6 minecraft:smooth_quartz
setblock ~23 ~4 ~7 minecraft:smooth_quartz
setblock ~23 ~4 ~8 minecraft:smooth_quartz
setblock ~23 ~4 ~9 minecraft:smooth_quartz
setblock ~23 ~4 ~10 minecraft:smooth_quartz
setblock ~23 ~4 ~11 minecraft:smooth_quartz
setblock ~23 ~4 ~12 minecraft:smooth_quartz
setblock ~23 ~4 ~13 minecraft:smooth_quartz
setblock ~23 ~4 ~14 minecraft:smooth_quartz
setblock ~23 ~4 ~15 minecraft:smooth_quartz
setblock ~23 ~4 ~16 minecraft:smooth_quartz
setblock ~23 ~4 ~17 minecraft:smooth_quartz
setblock ~23 ~4 ~18 minecraft:smooth_quartz
setblock ~23 ~4 ~19 minecraft:smooth_quartz
setblock ~23 ~4 ~20 minecraft:smooth_quartz
setblock ~23 ~4 ~21 minecraft:smooth_quartz
setblock ~23 ~4 ~22 minecraft:smooth_quartz
setblock ~23 ~4 ~23 minecraft:smooth_quartz
setblock ~23 ~4 ~24 minecraft:smooth_quartz
setblock ~23 ~4 ~25 minecraft:smooth_quartz
setblock ~23 ~5 ~25 minecraft:smooth_quartz
setblock ~23 ~6 ~25 minecraft:smooth_quartz
setblock ~23 ~4 ~26 minecraft:smooth_quartz
setblock ~23 ~5 ~26 minecraft:smooth_quartz
setblock ~23 ~6 ~26 minecraft:smooth_quartz
setblock ~23 ~4 ~27 minecraft:smooth_quartz
setblock ~23 ~5 ~27 minecraft:smooth_quartz
setblock ~23 ~6 ~27 minecraft:smooth_quartz
setblock ~24 ~4 ~4 minecraft:smooth_quartz
setblock ~24 ~5 ~4 minecraft:smooth_quartz
setblock ~24 ~6 ~4 minecraft:smooth_quartz
setblock ~24 ~4 ~5 minecraft:smooth_quartz
setblock ~24 ~5 ~5 minecraft:smooth_quartz
setblock ~24 ~6 ~5 minecraft:smooth_quartz
setblock ~24 ~4 ~6 minecraft:smooth_quartz
setblock ~24 ~5 ~6 minecraft:smooth_quartz
setblock ~24 ~6 ~6 minecraft:smooth_quartz
setblock ~24 ~4 ~7 minecraft:smooth_quartz
setblock ~24 ~4 ~8 minecraft:smooth_quartz
setblock ~24 ~4 ~9 minecraft:smooth_quartz
setblock ~24 ~4 ~10 minecraft:smooth_quartz
setblock ~24 ~4 ~11 minecraft:smooth_quartz
setblock ~24 ~4 ~12 minecraft:smooth_quartz
setblock ~24 ~4 ~13 minecraft:smooth_quartz
setblock ~24 ~4 ~14 minecraft:smooth_quartz
setblock ~24 ~4 ~15 minecraft:smooth_quartz
setblock ~24 ~4 ~16 minecraft:smooth_quartz
setblock ~24 ~4 ~17 minecraft:smooth_quartz
setblock ~24 ~4 ~18 minecraft:smooth_quartz
setblock ~24 ~4 ~19 minecraft:smooth_quartz
setblock ~24 ~4 ~20 minecraft:smooth_quartz
setblock ~24 ~4 ~21 minecraft:smooth_quartz
setblock ~24 ~4 ~22 minecraft:smooth_quartz
setblock ~24 ~4 ~23 minecraft:smooth_quartz
setblock ~24 ~4 ~24 minecraft:smooth_quartz
setblock ~24 ~5 ~24 minecraft:smooth_quartz
setblock ~24 ~6 ~24 minecraft:smooth_quartz
setblock ~24 ~4 ~25 minecraft:smooth_quartz
setblock ~24 ~5 ~25 minecraft:smooth_quartz
setblock ~24 ~6 ~25 minecraft:smooth_quartz
setblock ~24 ~4 ~26 minecraft:smooth_quartz
setblock ~24 ~5 ~26 minecraft:smooth_quartz
setblock ~24 ~6 ~26 minecraft:smooth_quartz
setblock ~25 ~4 ~5 minecraft:smooth_quartz
setblock ~25 ~5 ~5 minecraft:smooth_quartz
setblock ~25 ~6 ~5 minecraft:smooth_quartz
setblock ~25 ~4 ~6 minecraft:smooth_quartz
setblock ~25 ~5 ~6 minecraft:smooth_quartz
setblock ~25 ~6 ~6 minecraft:smooth_quartz
setblock ~25 ~4 ~7 minecraft:smooth_quartz
setblock ~25 ~5 ~7 minecraft:smooth_quartz
setblock ~25 ~6 ~7 minecraft:smooth_quartz
setblock ~25 ~4 ~8 minecraft:smooth_quartz
setblock ~25 ~4 ~9 minecraft:smooth_quartz
setblock ~25 ~4 ~10 minecraft:smooth_quartz
setblock ~25 ~4 ~11 minecraft:smooth_quartz
setblock ~25 ~4 ~12 minecraft:smooth_quartz
setblock ~25 ~4 ~13 minecraft:smooth_quartz
setblock ~25 ~4 ~14 minecraft:smooth_quartz
setblock ~25 ~4 ~15 minecraft:smooth_quartz
setblock ~25 ~4 ~16 minecraft:smooth_quartz
setblock ~25 ~4 ~17 minecraft:smooth_quartz
setblock ~25 ~4 ~18 minecraft:smooth_quartz
setblock ~25 ~4 ~19 minecraft:smooth_quartz
setblock ~25 ~4 ~20 minecraft:smooth_quartz
setblock ~25 ~4 ~21 minecraft:smooth_quartz
setblock ~25 ~4 ~22 minecraft:smooth_quartz
setblock ~25 ~4 ~23 minecraft:smooth_quartz
setblock ~25 ~5 ~23 minecraft:smooth_quartz
setblock ~25 ~6 ~23 minecraft:smooth_quartz
setblock ~25 ~4 ~24 minecraft:smooth_quartz
setblock ~25 ~5 ~24 minecraft:smooth_quartz
setblock ~25 ~6 ~24 minecraft:smooth_quartz
setblock ~25 ~4 ~25 minecraft:smooth_quartz
setblock ~25 ~5 ~25 minecraft:smooth_quartz
setblock ~25 ~6 ~25 minecraft:smooth_quartz
setblock ~26 ~4 ~6 minecraft:smooth_quartz
setblock ~26 ~5 ~6 minecraft:smooth_quartz
setblock ~26 ~6 ~6 minecraft:smooth_quartz
setblock ~26 ~4 ~7 minecraft:smooth_quartz
setblock ~26 ~5 ~7 minecraft:smooth_quartz
setblock ~26 ~6 ~7 minecraft:smooth_quartz
setblock ~26 ~4 ~8 minecraft:smooth_quartz
setblock ~26 ~5 ~8 minecraft:smooth_quartz
setblock ~26 ~6 ~8 minecraft:smooth_quartz
setblock ~26 ~4 ~9 minecraft:smooth_quartz
setblock ~26 ~5 ~9 minecraft:smooth_quartz
setblock ~26 ~6 ~9 minecraft:smooth_quartz
setblock ~26 ~4 ~10 minecraft:smooth_quartz
setblock ~26 ~4 ~11 minecraft:smooth_quartz
setblock ~26 ~4 ~12 minecraft:smooth_quartz
setblock ~26 ~4 ~13 minecraft:smooth_quartz
setblock ~26 ~4 ~14 minecraft:smooth_quartz
setblock ~26 ~4 ~15 minecraft:smooth_quartz
setblock ~26 ~4 ~16 minecraft:smooth_quartz
setblock ~26 ~4 ~17 minecraft:smooth_quartz
setblock ~26 ~4 ~18 minecraft:smooth_quartz
setblock ~26 ~4 ~19 minecraft:smooth_quartz
setblock ~26 ~4 ~20 minecraft:smooth_quartz
setblock ~26 ~4 ~21 minecraft:smooth_quartz
setblock ~26 ~5 ~21 minecraft:smooth_quartz
setblock ~26 ~6 ~21 minecraft:smooth_quartz
setblock ~26 ~4 ~22 minecraft:smooth_quartz
setblock ~26 ~5 ~22 minecraft:smooth_quartz
setblock ~26 ~6 ~22 minecraft:smooth_quartz
setblock ~26 ~4 ~23 minecraft:smooth_quartz
setblock ~26 ~5 ~23 minecraft:smooth_quartz
setblock ~26 ~6 ~23 minecraft:smooth_quartz
setblock ~26 ~4 ~24 minecraft:smooth_quartz
setblock ~26 ~5 ~24 minecraft:smooth_quartz
setblock ~26 ~6 ~24 minecraft:smooth_quartz
setblock ~27 ~4 ~7 minecraft:smooth_quartz
setblock ~27 ~5 ~7 minecraft:smooth_quartz
setblock ~27 ~6 ~7 minecraft:smooth_quartz
setblock ~27 ~4 ~8 minecraft:smooth_quartz
setblock ~27 ~5 ~8 minecraft:smooth_quartz
setblock ~27 ~6 ~8 minecraft:smooth_quartz
setblock ~27 ~4 ~9 minecraft:smooth_quartz
setblock ~27 ~5 ~9 minecraft:smooth_quartz
setblock ~27 ~6 ~9 minecraft:smooth_quartz
setblock ~27 ~4 ~10 minecraft:smooth_quartz
setblock ~27 ~5 ~10 minecraft:smooth_quartz
setblock ~27 ~6 ~10 minecraft:smooth_quartz
setblock ~27 ~4 ~11 minecraft:smooth_quartz
setblock ~27 ~5 ~11 minecraft:smooth_quartz
setblock ~27 ~6 ~11 minecraft:smooth_quartz
setblock ~27 ~4 ~12 minecraft:smooth_quartz
setblock ~27 ~4 ~13 minecraft:smooth_quartz
setblock ~27 ~4 ~14 minecraft:smooth_quartz
setblock ~27 ~4 ~15 minecraft:smooth_quartz
setblock ~27 ~4 ~16 minecraft:smooth_quartz
setblock ~27 ~4 ~17 minecraft:smooth_quartz
setblock ~27 ~4 ~18 minecraft:smooth_quartz
setblock ~27 ~4 ~19 minecraft:smooth_quartz
setblock ~27 ~5 ~19 minecraft:smooth_quartz
setblock ~27 ~6 ~19 minecraft:smooth_quartz
setblock ~27 ~4 ~20 minecraft:smooth_quartz
setblock ~27 ~5 ~20 minecraft:smooth_quartz
setblock ~27 ~6 ~20 minecraft:smooth_quartz
setblock ~27 ~4 ~21 minecraft:smooth_quartz
setblock ~27 ~5 ~21 minecraft:smooth_quartz
setblock ~27 ~6 ~21 minecraft:smooth_quartz
setblock ~27 ~4 ~22 minecraft:smooth_quartz
setblock ~27 ~5 ~22 minecraft:smooth_quartz
setblock ~27 ~6 ~22 minecraft:smooth_quartz
setblock ~27 ~4 ~23 minecraft:smooth_quartz
setblock ~27 ~5 ~23 minecraft:smooth_quartz
setblock ~27 ~6 ~23 minecraft:smooth_quartz
setblock ~28 ~4 ~9 minecraft:smooth_quartz
setblock ~28 ~5 ~9 minecraft:smooth_quartz
setblock ~28 ~6 ~9 minecraft:smooth_quartz
setblock ~28 ~4 ~10 minecraft:smooth_quartz
setblock ~28 ~5 ~10 minecraft:smooth_quartz
setblock ~28 ~6 ~10 minecraft:smooth_quartz
setblock ~28 ~4 ~11 minecraft:smooth_quartz
setblock ~28 ~5 ~11 minecraft:smooth_quartz
setblock ~28 ~6 ~11 minecraft:smooth_quartz
setblock ~28 ~4 ~12 minecraft:smooth_quartz
setblock ~28 ~5 ~12 minecraft:smooth_quartz
setblock ~28 ~6 ~12 minecraft:smooth_quartz
setblock ~28 ~4 ~13 minecraft:smooth_quartz
setblock ~28 ~5 ~13 minecraft:smooth_quartz
setblock ~28 ~6 ~13 minecraft:smooth_quartz
setblock ~28 ~4 ~14 minecraft:smooth_quartz
setblock ~28 ~5 ~14 minecraft:smooth_quartz
setblock ~28 ~6 ~14 minecraft:smooth_quartz
setblock ~28 ~4 ~15 minecraft:smooth_quartz
setblock ~28 ~5 ~15 minecraft:smooth_quartz
setblock ~28 ~6 ~15 minecraft:smooth_quartz
setblock ~28 ~4 ~16 minecraft:smooth_quartz
setblock ~28 ~5 ~16 minecraft:smooth_quartz
setblock ~28 ~6 ~16 minecraft:smooth_quartz
setblock ~28 ~4 ~17 minecraft:smooth_quartz
setblock ~28 ~5 ~17 minecraft:smooth_quartz
setblock ~28 ~6 ~17 minecraft:smooth_quartz
setblock ~28 ~4 ~18 minecraft:smooth_quartz
setblock ~28 ~5 ~18 minecraft:smooth_quartz
setblock ~28 ~6 ~18 minecraft:smooth_quartz
setblock ~28 ~4 ~19 minecraft:smooth_quartz
setblock ~28 ~5 ~19 minecraft:smooth_quartz
setblock ~28 ~6 ~19 minecraft:smooth_quartz
setblock ~28 ~4 ~20 minecraft:smooth_quartz
setblock ~28 ~5 ~20 minecraft:smooth_quartz
setblock ~28 ~6 ~20 minecraft:smooth_quartz
setblock ~28 ~4 ~21 minecraft:smooth_quartz
setblock ~28 ~5 ~21 minecraft:smooth_quartz
setblock ~28 ~6 ~21 minecraft:smooth_quartz
setblock ~29 ~4 ~12 minecraft:smooth_quartz
setblock ~29 ~5 ~12 minecraft:smooth_quartz
setblock ~29 ~6 ~12 minecraft:smooth_quartz
setblock ~29 ~4 ~13 minecraft:smooth_quartz
setblock ~29 ~5 ~13 minecraft:smooth_quartz
setblock ~29 ~6 ~13 minecraft:smooth_quartz
setblock ~29 ~4 ~14 minecraft:smooth_quartz
setblock ~29 ~5 ~14 minecraft:smooth_quartz
setblock ~29 ~6 ~14 minecraft:smooth_quartz
setblock ~29 ~4 ~15 minecraft:smooth_quartz
setblock ~29 ~5 ~15 minecraft:smooth_quartz
setblock ~29 ~6 ~15 minecraft:smooth_quartz
setblock ~29 ~4 ~16 minecraft:smooth_quartz
setblock ~29 ~5 ~16 minecraft:smooth_quartz
setblock ~29 ~6 ~16 minecraft:smooth_quartz
setblock ~29 ~4 ~17 minecraft:smooth_quartz
setblock ~29 ~5 ~17 minecraft:smooth_quartz
setblock ~29 ~6 ~17 minecraft:smooth_quartz
setblock ~29 ~4 ~18 minecraft:smooth_quartz
setblock ~29 ~5 ~18 minecraft:smooth_quartz
setblock ~29 ~6 ~18 minecraft:smooth_quartz
setblock ~3 ~7 ~12 minecraft:blackstone
setblock ~3 ~8 ~12 minecraft:smooth_quartz
setblock ~3 ~9 ~12 minecraft:smooth_quartz
setblock ~3 ~10 ~12 minecraft:smooth_quartz
setblock ~3 ~11 ~12 minecraft:smooth_quartz
setblock ~3 ~12 ~12 minecraft:smooth_quartz
setblock ~3 ~13 ~12 minecraft:smooth_quartz
setblock ~3 ~14 ~12 minecraft:smooth_quartz
setblock ~3 ~15 ~12 minecraft:smooth_quartz
setblock ~3 ~16 ~12 minecraft:smooth_quartz
setblock ~3 ~17 ~12 minecraft:smooth_quartz
setblock ~3 ~18 ~12 minecraft:smooth_quartz
setblock ~3 ~19 ~12 minecraft:smooth_quartz
setblock ~3 ~20 ~12 minecraft:smooth_quartz
setblock ~3 ~21 ~12 minecraft:smooth_quartz
setblock ~3 ~22 ~12 minecraft:smooth_quartz
setblock ~3 ~23 ~12 minecraft:smooth_quartz
setblock ~3 ~24 ~12 minecraft:blackstone
setblock ~3 ~7 ~13 minecraft:blackstone
setblock ~3 ~8 ~13 minecraft:smooth_quartz
setblock ~3 ~9 ~13 minecraft:smooth_quartz
setblock ~3 ~10 ~13 minecraft:smooth_quartz
setblock ~3 ~11 ~13 minecraft:smooth_quartz
setblock ~3 ~12 ~13 minecraft:smooth_quartz
setblock ~3 ~13 ~13 minecraft:smooth_quartz
setblock ~3 ~14 ~13 minecraft:smooth_quartz
setblock ~3 ~15 ~13 minecraft:smooth_quartz
setblock ~3 ~16 ~13 minecraft:smooth_quartz
setblock ~3 ~17 ~13 minecraft:smooth_quartz
setblock ~3 ~18 ~13 minecraft:smooth_quartz
setblock ~3 ~19 ~13 minecraft:smooth_quartz
setblock ~3 ~20 ~13 minecraft:smooth_quartz
setblock ~3 ~21 ~13 minecraft:smooth_quartz
setblock ~3 ~22 ~13 minecraft:smooth_quartz
setblock ~3 ~23 ~13 minecraft:smooth_quartz
setblock ~3 ~24 ~13 minecraft:blackstone
setblock ~3 ~7 ~14 minecraft:blackstone
setblock ~3 ~8 ~14 minecraft:smooth_quartz
setblock ~3 ~9 ~14 minecraft:smooth_quartz
setblock ~3 ~10 ~14 minecraft:smooth_quartz
setblock ~3 ~11 ~14 minecraft:smooth_quartz
setblock ~3 ~12 ~14 minecraft:smooth_quartz
setblock ~3 ~13 ~14 minecraft:smooth_quartz
setblock ~3 ~14 ~14 minecraft:smooth_quartz
setblock ~3 ~15 ~14 minecraft:smooth_quartz
setblock ~3 ~16 ~14 minecraft:smooth_quartz
setblock ~3 ~17 ~14 minecraft:smooth_quartz
setblock ~3 ~18 ~14 minecraft:smooth_quartz
setblock ~3 ~19 ~14 minecraft:smooth_quartz
setblock ~3 ~20 ~14 minecraft:smooth_quartz
setblock ~3 ~21 ~14 minecraft:smooth_quartz
setblock ~3 ~22 ~14 minecraft:smooth_quartz
setblock ~3 ~23 ~14 minecraft:smooth_quartz
setblock ~3 ~24 ~14 minecraft:blackstone
setblock ~3 ~7 ~15 minecraft:blackstone
setblock ~3 ~8 ~15 minecraft:smooth_quartz
setblock ~3 ~9 ~15 minecraft:smooth_quartz
setblock ~3 ~10 ~15 minecraft:smooth_quartz
setblock ~3 ~11 ~15 minecraft:smooth_quartz
setblock ~3 ~12 ~15 minecraft:smooth_quartz
setblock ~3 ~13 ~15 minecraft:smooth_quartz
setblock ~3 ~14 ~15 minecraft:smooth_quartz
setblock ~3 ~15 ~15 minecraft:smooth_quartz
setblock ~3 ~16 ~15 minecraft:smooth_quartz
setblock ~3 ~17 ~15 minecraft:smooth_quartz
setblock ~3 ~18 ~15 minecraft:smooth_quartz
setblock ~3 ~19 ~15 minecraft:smooth_quartz
setblock ~3 ~20 ~15 minecraft:smooth_quartz
setblock ~3 ~21 ~15 minecraft:smooth_quartz
setblock ~3 ~22 ~15 minecraft:smooth_quartz
setblock ~3 ~23 ~15 minecraft:smooth_quartz
setblock ~3 ~24 ~15 minecraft:blackstone
setblock ~3 ~7 ~16 minecraft:blackstone
setblock ~3 ~8 ~16 minecraft:smooth_quartz
setblock ~3 ~9 ~16 minecraft:smooth_quartz
setblock ~3 ~10 ~16 minecraft:smooth_quartz
setblock ~3 ~11 ~16 minecraft:smooth_quartz
setblock ~3 ~12 ~16 minecraft:smooth_quartz
setblock ~3 ~13 ~16 minecraft:smooth_quartz
setblock ~3 ~14 ~16 minecraft:smooth_quartz
setblock ~3 ~15 ~16 minecraft:smooth_quartz
setblock ~3 ~16 ~16 minecraft:smooth_quartz
setblock ~3 ~17 ~16 minecraft:smooth_quartz
setblock ~3 ~18 ~16 minecraft:smooth_quartz
setblock ~3 ~19 ~16 minecraft:smooth_quartz
setblock ~3 ~20 ~16 minecraft:smooth_quartz
setblock ~3 ~21 ~16 minecraft:smooth_quartz
setblock ~3 ~22 ~16 minecraft:smooth_quartz
setblock ~3 ~23 ~16 minecraft:smooth_quartz
setblock ~3 ~24 ~16 minecraft:blackstone
setblock ~3 ~7 ~17 minecraft:blackstone
setblock ~3 ~8 ~17 minecraft:smooth_quartz
setblock ~3 ~9 ~17 minecraft:smooth_quartz
setblock ~3 ~10 ~17 minecraft:smooth_quartz
setblock ~3 ~11 ~17 minecraft:smooth_quartz
setblock ~3 ~12 ~17 minecraft:smooth_quartz
setblock ~3 ~13 ~17 minecraft:smooth_quartz
setblock ~3 ~14 ~17 minecraft:smooth_quartz
setblock ~3 ~15 ~17 minecraft:smooth_quartz
setblock ~3 ~16 ~17 minecraft:smooth_quartz
setblock ~3 ~17 ~17 minecraft:smooth_quartz
setblock ~3 ~18 ~17 minecraft:smooth_quartz
setblock ~3 ~19 ~17 minecraft:smooth_quartz
setblock ~3 ~20 ~17 minecraft:smooth_quartz
